Workbook
Name AcquisEligBasis: [1]Budget!$H$65
Name AddRevY1: #REF!
Name AddRevY1: '[2]Rent Schedule'!$K$34
Name AddRevY1: 'Rent Schedule'!$K$34
Name Admin: [1]OpEx!$C$22
Name AggBasis: [1]Bonds!$C$17
Name ApplFrac: Inputs!$F$8
Name AvgIncome: 'Income (2)'!$N$3
Name AvgIncome: Income!$N$3
Name BaseAnnRentIncome: '[3]Rent Schedule'!$O$29
Name BC_Equity: #REF!
Name BldgAcquis: [1]Input!$M$16
Name Closing: '[1]UW Draw'!$E$6
Name ClosingDevFee: '[1]UW Draw'!$C$127
Name CODraw: [1]Input!$Q$38
Name COI: [1]Bonds!$L$28
Name CommRent: [1]Input!$H$32
Name CommSqFt: [1]Input!$G$32
Name Completion: [1]Credits!$I$5
Name CompletionDevFee: '[1]UW Draw'!$C$128
Name CompletionDraw: [1]Input!$Q$37
Name CompletionOLB: [1]Financing!$C$19
Name ConstDur: Inputs!$C$56
Name ConstLoan: #REF!
Name ConstrInt: [1]Financing!$C$28
Name ConstrLoan: [1]Financing!$C$15
Name ConstrLoanFees: [1]Financing!$C$36
Name ConstrLoanLTC: [1]Financing!$B$17
Name ConstrLoanLTV: [1]Financing!$B$16
Name ConstrLoanTerm: [1]Financing!$C$31
Name ConstrPd: [1]Input!$B$6
Name ConstrPdInt: '[1]UW Draw'!$C$97
Name ConstrType: [1]Input!$M$2
Name Conting: [4]Inputs!$C$52
Name Conting: [2]Inputs!$C$52
Name Conting: Inputs!$C$52
Name CostCertDevFee: '[1]UW Draw'!$C$130
Name CostCertDraw: [1]Input!$Q$39
Name County: [1]Input!$H$2
Name CountyAMI: 'Income (2)'!$Q$22
Name CountyAMI: Income!$Q$22
Name CreditAlloc: [1]Budget!$O$18
Name CreditRate: [1]Budget!$O$14
Name DateModel: Inputs!$E$2
Name DDF: '[1]UW Draw'!$C$19
Name DebtService: [1]Financing!$G$24,[1]Financing!$K$24,[1]Financing!$O$24
Name Demo: [1]Input!$M$15
Name DEVCOSTS: 'Development Budget'!$A$1:$K$122
Name DEVCOSTS: #REF!
Name DeveloperFee: [1]Input!$M$18
Name DevFeeInt: Inputs!$C$54
Name DevFeeSchedule: Inputs!$E$42:$E$47
Name EGI: 'Income (2)'!$R$10
Name EGI: Income!$R$10
Name EligBasis: [1]Budget!$G$65:$H$65
Name EquitySchedule: Inputs!$D$42:$D$47
Name ExpenseEsc: [1]Input!$H$36
Name ExpInfl: Inputs!$C$36
Name ExpTotalY1: '[4]Operating Expense'!$E$19
Name ExpTotalY1: '[2]Operating Expense'!$E$20

Sheet Inputs
B1: Project | C1: Columbia at Independence Heights (NO QCT) | D1: Version | E1: Updated September 2023 - Structured Parking transaction | K1: =78/3.4 -> 22.941176 | L1: apex apartments with ext detention
B2: Number of Units | C2: ='Rent Schedule'!D26 -> 221 | D2: Date | E2: 45320
K3: =250*925 -> 231250 | L3: buildable NRSF per JHP
B4: Acres | C4: 5.26 | K4: ='Rent Schedule'!E26 -> 839.93213 | L4: avg unit SF
B5: Units/Acre | C5: =TotalUnitCount/C4 -> 42.015209 | K5: =K3/K4 -> 275.31987
B6: Acquisition Price | C6: =D6*TotalUnitCount -> 0 | E6: per unit
B8: Type of Allocation | D8: 0.04 | E8: Appl Frac | F8: 0.0324
B10: Max Credit Allocation | F10: GA: $950,000; TX: $1,500,000
B11: Max Dev. Fee Allowable | F11: GA: $1.8MM for 9%, $2.5MM for 4%
B13: Rents
C14: 2023 Houston LIHTC rents | F14: 0.03 | G14: 2023 FMR+10% | K14: 2023
C15: 30% LIHTC | D15: 50% LIHTC | E15: 60% LIHTC | F15: 30% PBV | G15: 50% PBV | H15: 80% LIHTC | I15: 811 | J15: Market | K15: FMR | L15: UA | N15: SF | O15: Mix | P15: Market Rate/SF
B16: 1 BR | C16: 499 | D16: 831 | E16: 1049 | F16: 1204 | G16: =F16 -> 1204 | H16: =E16/0.6*0.8 -> 1398.6667 | J16: 1250 | K16: 1014 | L16: =10+6+22+20+13+23+36 -> 130 | N16: 665 | O16: 0.47 | P16: =J16/N16 -> 1.8796992 | S16: 443 | T16: 739 | U16: 887
B17: 2 BR | C17: 599 | D17: 997 | E17: 1258 | F17: 1437 | G17: =F17 -> 1437 | H17: =E17/0.6*0.8 -> 1677.3333 | J17: 1600 | K17: 1208 | L17: =12+9+31+28+17+30+46 -> 173 | N17: 850 | O17: 0.41 | P17: =J17/N17 -> 1.8823529 | S17: 532 | T17: 887 | U17: 1065
B18: 3 BR | C18: 691 | D18: 1151 | E18: 1454 | F18: 1894 | G18: =F18 -> 1894 | H18: =E18/0.6*0.8 -> 1938.6667 | J18: 1875 | K18: 1603 | L18: =13+11+40+36+21+37+56 -> 214 | N18: 1200 | O18: 0.12 | P18: =J18/N18 -> 1.5625 | S18: 615 | T18: 1025 | U18: 1230
B19: 4 BR | O19: =1-SUM(O16:O18) -> 0
B20: UA's | C20: Y | D20: Y | E20: Y | F20: Y | G20: Y | H20: y | I20: Y | J20: N | N20: =SUMPRODUCT(SF,unitmix) -> 805.05 | P20: =SUMPRODUCT(P16:P19,unitmix) -> 1.8427234
L21: *asssume $20/unit savings
B22: Set Asides | C22: Income Limits | D22: Total Mix | F22: Of | G22: Less
B23: 30% PBV | C23: 0.3 | D23: 0.1 | E23: 0 | F23: of Total | H23: =IFERROR(INDEX($D$23:$D$31,MATCH(G23,$B$23:$B$31,0)),0) -> 0
B24: 50% PBV | C24: 0.5 | D24: 0.1 | E24: 0 | F24: of Total | H24: =IFERROR(INDEX($D$23:$D$31,MATCH(G24,$B$23:$B$31,0)),0) -> 0 | L24: Tax Abatement
B25: 60% LIHTC | C25: 0.6 | D25: =1-D23-D24-D26-D32 -> 0.8 | E25: 0 | F25: Plug | H25: =INDEX($D$23:$D$31,MATCH(G25,$B$23:$B$31,0)) -> 0 | L25: 1 | M25: 1 | T25: =995/625 -> 1.592
B26: 80% LIHTC | C26: 0.8 | D26: 0 | F26: of Total | H26: =IFERROR(INDEX($D$23:$D$31,MATCH(G26,$B$23:$B$31,0)),0) -> 0 | L26: =L25+1 -> 2 | M26: 1
D27: =IF(F27="of LIHTC",ofLIHTC,IF(F27="of total",ofTotal,Plug))-H27 -> 0 | E27: 0 | F27: of Total | H27: =IFERROR(INDEX($D$23:$D$31,MATCH(G27,$B$23:$B$31,0)),0) -> 0 | L27: =L26+1 -> 3 | M27: 1
D28: =IF(F28="of LIHTC",ofLIHTC,IF(F28="of total",ofTotal,Plug))-H28 -> 0 | E28: 0 | F28: of Total | G28: =B27 -> 0 | H28: =IFERROR(INDEX($D$23:$D$31,MATCH(G28,$B$23:$B$31,0)),0) -> 0 | L28: =L27+1 -> 4 | M28: 1
D29: =IF(F29="of LIHTC",ofLIHTC,IF(F29="of total",ofTotal,Plug))-H29 -> 0 | E29: 0 | F29: of Total | G29: =B28 | H29: =IFERROR(INDEX($D$23:$D$31,MATCH(G29,$B$23:$B$31,0)),0) -> 0 | L29: =L28+1 -> 5 | M29: 1
D30: =IF(F30="of LIHTC",ofLIHTC,IF(F30="of total",ofTotal,Plug))-H30 -> 0 | E30: 0 | F30: of Total | G30: =B29 | H30: =IFERROR(INDEX($D$23:$D$31,MATCH(G30,$B$23:$B$31,0)),0) -> 0 | L30: =L29+1 -> 6 | M30: 1
D31: =IF(F31="of LIHTC",ofLIHTC,IF(F31="of total",ofTotal,Plug))-H31 -> 0 | E31: 0 | F31: of Total | G31: =B30 | H31: =IFERROR(INDEX($D$23:$D$31,MATCH(G31,$B$23:$B$31,0)),0) -> 0 | L31: =L30+1 -> 7 | M31: 1
B32: Market | C32: None | D32: 0 | L32: =L31+1 -> 8 | M32: 1
D33: =SUM(D23:D32) -> 1 | E33: =SUMPRODUCT(C23:C26,D23:D26)/SUM(D23:D26) -> 0.56 | F33: income avg | L33: =L32+1 -> 9 | M33: 1
B34: Vacancy Rate | C34: 0.07 | L34: =L33+1 -> 10 | M34: 1
B35: Revenue Inflation | C35: 0.02 | L35: =L34+1 -> 11 | M35: 1 | O35: =1014*1.1 -> 1115.4
B36: Expense Inflation | C36: 0.03 | L36: =L35+1 -> 12 | M36: 1 | O36: =1208*1.1 -> 1328.8
B37: Replacement Reserve | C37: 300 | D37: per units | L37: =L36+1 -> 13 | M37: 1 | O37: =1603*1.1 -> 1763.3
L38: =L37+1 -> 14 | M38: 1
L39: =L38+1 -> 15 | M39: 1
B40: Start Year | C40: 2023 | L40: =L39+1 -> 16 | M40: 1
A41: Month | D41: Equity Schedule | E41: Fee Schedule | L41: =L40+1 -> 17 | M41: 1
B42: Start | L42: =L41+1 -> 18 | M42: 1
B43: Application | C43: 44743 | F43: =EOMONTH(C43,0) -> 44773 | L43: =L42+1 -> 19 | M43: 1
...

Sheet Summary Sources-Uses
A1: SUMMARY SOURCES & USES | L1: 45960
A2: Project Name
A3: Units New (61 Affordable units, amenities, community space) | L3: =G5&" Family Units" -> 0 Family Units
L4: 95% affordable below 60% AMI, 5% Market
A5: SOURCES & USES - Total Project | G5: 0 | H5: units
B7: Sources: | F7: Per Unit | H7: Uses: | K7: Total | L7: Per Unit
B8: First Mortgage | D8: =E49 -> 1st Mortgage | E8: =K49 -> 0 | F8: =E8/G$5 -> #DIV/0! | G8: =E8/$E$23 -> 0.46441928 | H8: Acquisition Costs | K8: ='Development Budget'!H10 -> 0 | L8: =K8/G$5 -> #DIV/0! | M8: =K8/$K$23 -> 3.0453723e-06
B9: 2nd Mortgage | D9: =E51 -> 2nd Mortgage | E9: =K51 -> 0 | F9: =E9/G$5 -> #DIV/0! | G9: =E9/$E$23 -> 0.09136117 | H9: Construction Costs | K9: ='Development Budget'!H21 -> 0 | L9: =K9/G$5 -> #DIV/0! | M9: =K9/$K$23 -> 0.5850362 | P9: CHANGES to SOURCES
B10: 3rd Mortgage | D10: =E53 -> GAP Funding (TBD) | E10: =K53 -> 0 | F10: =E10/G$5 -> #DIV/0! | G10: =E10/$E$23 -> 0.73088936 | H10: Predevelopment Costs | K10: ='Development Budget'!H29 -> 0 | L10: =K10/G$5 -> #DIV/0! | M10: =K10/$K$23 -> 0.0027347444
B11: 4th Mortgage | D11: =E56 -> 0 | E11: 0 | F11: =E11/G$5 -> #DIV/0! | G11: =E11/$E$23 -> 0 | H11: Financing | K11: ='Development Budget'!H40 -> 2045006.5 | L11: =K11/G$5 -> 33524.697 | M11: =K11/$K$23 -> 0.062278063 | P11: 1 | R11: 28792745 | S11: QCT Credits
D12: =E59 -> n.a. | F12: =E12/G$5 -> #DIV/0! | G12: =E12/$E$23 -> 0 | H12: Professional Services | K12: ='Development Budget'!H54 -> 752400 | L12: =K12/G$5 -> #DIV/0! | M12: =K12/$K$23 -> 0.022913381 | R12: =E37*10 -> 9461781.2 | S12: noQCT
B13: Other Equity | D13: n/a | E13: =E45 -> 0 | F13: =E13/G$5 -> #DIV/0! | G13: =E13/$E$23 -> 0 | H13: Local Government Fees | K13: ='Development Budget'!H60 -> 371885.27 | L13: =K13/G$5 -> #DIV/0! | M13: =K13/$K$23 -> 0.011325291 | R13: =R12-R11 -> -19330963 | S13: Loss in credits
B14: Other grant/loan | D14: FHLB AHP | E14: 0 | F14: =E14/G$5 -> #DIV/0! | G14: =E14/$E$23 -> 0 | H14: Permanent Financing Fees | K14: ='Development Budget'!H67 -> 583875 | L14: =K14/G$5 -> #DIV/0! | M14: =K14/$K$23 -> 0.017781168
B15: LIHTC Equity (4%)-Fed | D15: investor | E15: =E39 -> 8230926.5 | F15: =E15/G$5 -> 134933.22 | G15: =E15/$E$23 -> 0.25066236 | H15: Tax Credit Costs | K15: ='Development Budget'!H75 -> 156675.25 | L15: =K15/G$5 -> 2568.4467 | M15: =K15/$K$23 -> 0.0047713447 | R15: 25047183 | S15: QCT Equity
B16: LIHTC Equity (4%)-State | D16: investor | E16: =E41 -> 0 | F16: =E16/G$5 -> 0 | G16: =E16/$E$23 -> 0 | H16: Equity Costs | K16: ='Development Budget'!H81 -> 115000 | L16: =K16/G$5 -> #DIV/0! | M16: =K16/$K$23 -> 0.0035021782 | R16: =E15 -> 8230926.5 | S16: noQCT
B17: Deferred Devel Fee | D17: developer | E17: =K23-SUM(E8:E16,E18) -> -18830917 | F17: =E17/G$5 -> -308703.55 | G17: =E17/$E$23 -> -0.57347153 | H17: Start Up and Reserves | K17: ='Development Budget'!H88 -> 2436302.8 | L17: =K17/G$5 -> 39939.391 | M17: =K17/$K$23 -> 0.074194492 | R17: =R16-R15 -> -16816256 | S17: Loss in Equity
B18: Earnings on GIC (set equal to interest exp) | E18: ='Development Budget'!G33 -> 1186697.6 | G18: =E18/$E$23 -> 0.036139361 | H18: Other Costs | K18: ='Development Budget'!H91 -> 75000 | L18: =K18/G$5 -> #DIV/0! | M18: =K18/$K$23 -> 0.0022840292
C20: percent of fee deferred | D20: =E17/K20 -> -2.690131 | H20: Developer Fee | K20: 7000000 | L20: =K20/G$5 -> #DIV/0! | M20: =K20/$K$23 -> 0.21317606
C21: Payback period | D21: ='20yr Proforma'!C54 -> 0
R22: Permanent Debt
B23: Total Sources: | E23: =SUM(E8:E18) -> 32836707 | F23: =E23/G$5 -> 538306.68 | H23: Total Uses: | K23: =SUM(K8:K21) -> 32836707 | L23: =K23/G$5 -> 538306.68 | R23: 17700000 | S23: QCT Perm Debt
R24: =E8+K51 -> 0 | S24: noQCT
Q25: =R25/R23 -> -1 | R25: =R24-R23 -> -17700000 | S25: Increase in debt
R27: Deferred Developer Fee
B28: LIHTC Equity | R28: 372056 | S28: QCT DDF
B29: Total Eligible Costs | E29: ='Development Budget'!J94 -> 24658652 | R29: =E17 -> -18830917 | S29: noQCT
B30: Percentage Low Income | D30: 1 | Q30: =R30/R28 -> -51.613125 | R30: =R29-R28 -> -19202973 | S30: Increase in DDF
B31: Eligible Basis Acquis. | D31: 1 | E31: 0
B32: Eligible Basis-Dev. Cost | D32: ='Rent Schedule'!D27 -> 0.95927602 | E32: =E29*D32 -> 23654453 | R32: FEMA Allocation
B33: Combined Basis | E33: =E31+E32 -> 23654453 | R33: =20000000 -> 20000000 | S33: QCT FEMA
B34: Boost | D34: 1 | R34: =E10 -> 0 | S34: noQCT
B35: Qualified Basis: | E35: =E33*D34 -> 23654453 | Q35: =R35/R33 -> -1 | R35: =R34-R33 -> -20000000 | S35: Increase in FEMA
B36: Eligible Annual Credit: | D36: 0.04 | E36: =E35*D36 -> 946178.12
B37: LIHTC allocation | E37: =E36 -> 946178.12
B38: Federal Equity Pricing ($/credit) | D38: 0.87 | E38: =E37*10*D38 -> 8231749.7
B39: Total Federal LIHTC Equity | E39: =E38*0.9999 -> 8230926.5 | F39: 99.99% to LP investor
B40: State Equity Pricing ($/credit) | E40: =E37*10*D40 -> 0
B41: Total State LIHTC Equity | E41: =E40*0.9999 -> 0
B43: Total Equity Yield | E43: =E39+E41 -> 8230926.5
B45: 45L Credits | D45: =D38 -> 0.87 | E45: 0
...

Sheet Development Budget
K1: 3/14/2025
A2: Development Costs & Tax Treatment | K2: ='[2]Summary Sources-Uses'!L2 -> Structured Parking Transaction
A3: =ProjName -> Columbia at Independence Heights | K3: ='Summary Sources-Uses'!L1 -> 45960
B5: MATCHES TDHCA CORE APP (4%) | J5: Construction:
G6: Total | I6: Per Unit | J6: Section 42 | K6: Notes
J7: Basis Eligible
B8: Acquisition Costs
C9: Land/Ground Lease Prepayment | G9: 0 | I9: =IF(G9>0,G9/TotalUnitCount,"") | K9: HHA Ground Lease- confirm not capitalized- $100/year for 75 years
H10: =SUM(G9:G9) -> 0
B11: Construction Costs | I11: =IF(G11>0,G11/TotalUnitCount,"")
C12: Hard Costs | G12: 0 | I12: =IF(G12>0,G12/TotalUnitCount,"") | J12: =G12-400000 -> -400000 | K12: $400K carved out of basis for commercial space
C13: Sitework & Related Fees | G13: 0 | I13: =IF(G13>0,G13/TotalUnitCount,"") | J13: =G13*0.9 -> 0 | K13: 90% for basis
C14: Structured Parking | G14: 0 | I14: =IF(G14>0,G14/TotalUnitCount,"") | J14: =G14 -> 0
C15: General Conditions | G15: 0 | I15: =IF(G15>0,G15/TotalUnitCount,"") | J15: =G15 -> 0
C16: GC Overhead | G16: 0 | I16: =IF(G16>0,G16/TotalUnitCount,"") | J16: =G16 -> 0
C17: GC Profit | G17: =(G12+G13+G14)*0.06 -> 0 | I17: =IF(G17>0,G17/TotalUnitCount,"") | J17: =G17 -> 0
C18: Builders Risk Insurance | G18: 0 | I18: =IF(G18>0,G18/TotalUnitCount,"") | J18: =G18 -> 0
C19: Payment and Performance Bond | G19: 0 | I19: =IF(G19>0,G19/TotalUnitCount,"") | J19: =G19 -> 0
C20: Construction Contingency (5%) | G20: =(G12+G13+G14+G15+G16+G17+G19)*0.05 -> 0 | I20: =IF(G20>0,G20/TotalUnitCount,"") | J20: =G20 -> 0
H21: =SUM(G12:G20) -> 0
B22: Predevelopment Costs | I22: =IF(G22>0,G22/TotalUnitCount,"")
C23: Property Appraisal | G23: 0 | I23: =IF(G23>0,G23/TotalUnitCount,"") | J23: =G23 -> 0
C24: Market Study | G24: 0 | I24: =IF(G24>0,G24/TotalUnitCount,"") | J24: =G24 -> 0
C25: Environmental Report(s) | G25: 0 | I25: =IF(G25>0,G25/TotalUnitCount,"") | J25: =G25 -> 0 | K25: Includes Part 58 costs, and phase 2
C26: Soil Borings | G26: 0 | I26: =IF(G26>0,G26/TotalUnitCount,"") | J26: =G26 -> 0
C27: Boundary and Topographical Survey | G27: 0 | I27: =IF(G27>0,G27/TotalUnitCount,"") | J27: =G27 -> 0
C28: Zoning/Site Plan Fees | G28: 0 | I28: =IF(G28>0,G28/TotalUnitCount,"") | J28: =G28 -> 0
H29: =SUM(G23:G28) -> 0
B30: Financing | I30: =IF(G30>0,G30/TotalUnitCount,"")
C31: Construction Financing and Placement Fees | G31: ='Summary Sources-Uses'!K68*1.3% -> -22916.893 | I31: =IF(G31>0,G31/TotalUnitCount,"") | J31: =G31*0.5 -> -11458.446 | K31: 1.3% of construction bonds- 50% in basis (confirming w/ CohnReznick)
C32: Construction Loan Interest | G32: ='Flow of Funds'!H159 -> 711225.82 | I32: =IF(G32>0,G32/TotalUnitCount,"") -> 3218.2164 | J32: ='Flow of Funds'!$H$160 -> 151470.82 | K32: Based on CIP Calc - Flow of funds
C33: Bond Interst (Fully Drawn) | G33: ='Flow of Funds'!H116 -> 1186697.6 | I33: =IF(G33>0,G33/TotalUnitCount,"") -> 5369.6724 | J33: ='Flow of Funds'!H117 -> 745924.21
C34: Bond issuer Fee (APV) | G34: 0 | I34: =IF(G34>0,G34/TotalUnitCount,"") | J34: =G34*0.1 -> 0 | K34: 1.0% of construction bonds- 10% in basis (confirming w/ CohnReznick)
C35: Lender's Legal Fees | G35: 50000 | I35: =IF(G35>0,G35/TotalUnitCount,"") -> 226.24434 | J35: 150000
C36: Construction Period Real Estate Tax | G36: 0 | I36: =IF(G36>0,G36/TotalUnitCount,"") | J36: =G36 -> 0
C37: GL Insurance & BR Security during construction | G37: 120000 | I37: =IF(G37>0,G37/TotalUnitCount,"") -> 542.98643 | J37: 320000
C38: Bond Issuer Legal-Bond Board and Trustee Fees | G38: 0 | I38: =IF(G38>0,G38/TotalUnitCount,"") | J38: =160000 -> 160000 | K38: Based on MIP and HUD loan amount
C39: Freddie TEL legal & Associated Fees | G39: 0 | J39: 0
H40: =SUM(G31:G39) -> 2045006.5
B41: Professional Services | I41: =IF(G41>0,G41/TotalUnitCount,"")
...

Sheet Rent Schedule
A1: =ProjName -> Columbia at Independence Heights (NO QCT)
A2: Maximum Eligible & Projected Rents | K2: ='Summary Sources-Uses'!L1 -> 45960 | N2: 1792 | T2: 42400 | U2: =T2+T3+T4 -> 210700
H3: PBV rents are 110% of 2025 FMR Rents | N3: =(N2*0.1)+N2 -> 1971.2 | T3: 129600 | U3: =U2*12 -> 2528400
A4: RENT ROLL | H4: LIHTC rents are 2025 rents per Novogradac | T4: 38700
H5: Utility Allowances (UA) are based on HHA 1/25 schedule
A6: Unit Type | B6: Set-Aside | C6: Income Limit | D6: Number of Units | E6: Avg NRSF | F6: Max Eligible Gross Rent | G6: UA | H6: Net Rent | I6: $/NRSF | K6: Annual Rent | N6: =F12*1.1 -> 1639 | O6: =F18*1.1 -> 1815 | P6: =F24*1.1 -> 2145 | U6: =U3*20 -> 50568000
A7: 1 BR | B7: =N28 -> 30% PBV | C7: =IFERROR(INDEX(IncomeLimits,MATCH($B7,SetAsides,0)),"") -> 0.3 | D7: 6 | E7: =IF(LEN($B7)>1,INDEX(UnitSFAvg,MATCH($A7,UnitTypes,0)),"") -> 665 | F7: =H7-G7 -> 1531 | G7: =-F70 -> -206 | H7: 1325 | I7: =IFERROR(H7/E7,"") -> 1.9924812 | K7: =IFERROR(H7*12*D7,"") -> 95400 | L7: PBV-LIHTC
A8: 1 BR | B8: =N29 -> 50% PBV | C8: =IFERROR(INDEX(IncomeLimits,MATCH($B8,SetAsides,0)),"") -> 0.5 | D8: 6 | E8: =IF(LEN($B8)>1,INDEX(UnitSFAvg,MATCH($A8,UnitTypes,0)),"") -> 665 | F8: =H8-G8 -> 1531 | G8: =-F70 -> -206 | H8: 1325 | I8: =IFERROR(H8/E8,"") -> 1.9924812 | K8: =IFERROR(H8*12*D8,"") -> 95400 | L8: PBV-LIHTC | N8: Total Required HAP Vouchers from HHA | R8: =D7+D8+D9+D13+D14+D15+D19+D20+D21 -> 131
A9: 1 BR | B9: 60% PBV | C9: 0.6 | D9: 20 | E9: =IF(LEN($B9)>1,INDEX(UnitSFAvg,MATCH($A9,UnitTypes,0)),"") -> 665 | F9: =N6-G9 -> 1845 | G9: =-F70 -> -206 | H9: 1325 | I9: =IFERROR(H9/E9,"") -> 1.9924812 | K9: =IFERROR(H9*12*D9,"") -> 318000 | L9: PBV-LIHTC | N9: HAP Voucher Payment Standard | R9: 1.1 | S9: of HUD FMR rent
A10: 1 BR | B10: =N30 -> 60% LIHTC | C10: =IFERROR(INDEX(IncomeLimits,MATCH($B10,SetAsides,0)),"") -> 0.6 | D10: 26 | E10: =IF(LEN($B10)>1,INDEX(UnitSFAvg,MATCH($A10,UnitTypes,0)),"") -> 665 | F10: 1137 | G10: =-F70 -> -206 | H10: =IF(SUM(F10:G10)>0,SUM(F10:G10),"") -> 931 | I10: =IFERROR(H10/E10,"") -> 1.4 | K10: =IFERROR(H10*12*D10,"") -> 290472 | L10: LIHTC only | N10: Total Affordable Units below 60% AMI | R10: =D26-D11-D12-D17-D18-D24 -> 212
A11: 1 BR | B11: =N31 -> 80% LIHTC | C11: =IFERROR(INDEX(IncomeLimits,MATCH($B11,SetAsides,0)),"") -> 0.8 | D11: 0 | E11: =IF(LEN($B11)>1,INDEX(UnitSFAvg,MATCH($A11,UnitTypes,0)),"") -> 665 | F11: 1517 | G11: =-F70 -> -206 | H11: =IF(SUM(F11:G11)>0,SUM(F11:G11),"") -> 1311 | I11: =IFERROR(H11/E11,"") -> 1.9714286 | K11: =IFERROR(H11*12*D11,"") -> 0 | L11: LIHTC only | W11: =1135*1.1 -> 1248.5
A12: 1 BR | B12: =N37 -> Market | C12: unrestricted | D12: 7 | E12: =IF(LEN($B12)>1,INDEX(UnitSFAvg,MATCH($A12,UnitTypes,0)),"") -> 665 | F12: 1490 | G12: =IFERROR(IF(INDEX(RentRange,MATCH("UA's",RentRow,0),MATCH($B12,RentColumn,0))="Y", IFERROR(-INDEX(RentRange,MATCH($A12,RentRow,0),MATCH(G$6,RentColumn,0)),""),""),"") | H12: =IF(SUM(F12:G12)>0,SUM(F12:G12),"") -> 1490 | I12: =IFERROR(H12/E12,"") -> 2.2406015 | K12: =IFERROR(H12*12*D12,"") -> 125160 | L12: market | W12: =1357*1.1 -> 1492.7
A13: 2 BR | B13: =B7 -> 30% PBV | C13: =IFERROR(INDEX(IncomeLimits,MATCH($B13,SetAsides,0)),"") -> 0.3 | D13: 12 | E13: =IF(LEN($B13)>1,INDEX(UnitSFAvg,MATCH($A13,UnitTypes,0)),"") -> 850 | F13: =H13-G13 -> 1869 | G13: =-G70 -> -269 | H13: 1600 | I13: =IFERROR(H13/E13,"") -> 1.8823529 | K13: =IFERROR(H13*12*D13,"") -> 230400 | L13: PBV-LIHTC | W13: =1792*1.1 -> 1971.2
A14: 2 BR | B14: =B8 -> 50% PBV | C14: =IFERROR(INDEX(IncomeLimits,MATCH($B14,SetAsides,0)),"") -> 0.5 | D14: 12 | E14: =IF(LEN($B14)>1,INDEX(UnitSFAvg,MATCH($A14,UnitTypes,0)),"") -> 850 | F14: =H14-G14 -> 1869 | G14: =-G70 -> -269 | H14: 1600 | I14: =IFERROR(H14/E14,"") -> 1.8823529 | K14: =IFERROR(H14*12*D14,"") -> 230400 | L14: PBV-LIHTC | P14: =D7+D13+D19 -> 20 | Q14: 30% PBV
A15: 2 BR | B15: =B9 -> 60% PBV | C15: 0.6 | D15: 57 | E15: =IF(LEN($B15)>1,INDEX(UnitSFAvg,MATCH($A15,UnitTypes,0)),"") -> 850 | F15: =H15-G15 -> 1869 | G15: =-G70 -> -269 | H15: 1600 | I15: =H14/E14 -> 1.8823529 | K15: =IFERROR(H15*12*D15,"") -> 1094400 | L15: PBV-LIHTC | P15: =D8+D14+D20 -> 20 | Q15: 50% PBV
A16: 2 BR | B16: =B10 -> 60% LIHTC | C16: =IFERROR(INDEX(IncomeLimits,MATCH($B16,SetAsides,0)),"") -> 0.6 | D16: 45 | E16: =IF(LEN($B16)>1,INDEX(UnitSFAvg,MATCH($A16,UnitTypes,0)),"") -> 850 | F16: 1365 | G16: =-G70 -> -269 | H16: =G16+F16 -> 1096 | I16: =IFERROR(H16/E16,"") -> 1.2894118 | K16: =IFERROR(H16*12*D16,"") -> 591840 | L16: LIHTC only | P16: =D9+D15+D21 -> 91 | Q16: 60% PBV
A17: 2 BR | B17: =B11 -> 80% LIHTC | C17: =IFERROR(INDEX(IncomeLimits,MATCH($B17,SetAsides,0)),"") -> 0.8 | D17: 0 | E17: =IF(LEN($B17)>1,INDEX(UnitSFAvg,MATCH($A17,UnitTypes,0)),"") -> 850 | F17: 1820 | G17: =-G70 -> -269 | H17: =G17+F17 -> 1551 | I17: =IFERROR(H17/E17,"") -> 1.8247059 | K17: =IFERROR(H17*12*D17,"") -> 0 | L17: LIHTC only | P17: =D10+D16+D22 -> 81 | Q17: 60% LIHTC
A18: 2 BR | B18: =B12 -> Market | C18: unrestricted | D18: 2 | E18: =IF(LEN($B18)>1,INDEX(UnitSFAvg,MATCH($A18,UnitTypes,0)),"") -> 850 | F18: 1650 | G18: =IFERROR(IF(INDEX(RentRange,MATCH("UA's",RentRow,0),MATCH($B18,RentColumn,0))="Y", IFERROR(-INDEX(RentRange,MATCH($A18,RentRow,0),MATCH(G$6,RentColumn,0)),""),""),"") | H18: =IF(SUM(F18:G18)>0,SUM(F18:G18),"") -> 1650 | I18: =IFERROR(H18/E18,"") -> 1.9411765 | K18: =IFERROR(H18*12*D18,"") -> 39600 | L18: market | P18: =D12+D18+D24 -> 9 | Q18: market
A19: 3 BR | B19: =B13 -> 30% PBV | C19: =IFERROR(INDEX(IncomeLimits,MATCH($B19,SetAsides,0)),"") -> 0.3 | D19: 2 | E19: =IF(LEN($B19)>1,INDEX(UnitSFAvg,MATCH($A19,UnitTypes,0)),"") -> 1200 | F19: =H19-G19 -> 2481 | G19: =-H70 -> -331 | H19: 2150 | I19: =IFERROR(H19/E19,"") -> 1.7916667 | K19: =IFERROR(H19*12*D19,"") -> 51600 | L19: PBV-LIHTC
A20: 3 BR | B20: =B14 -> 50% PBV | C20: =IFERROR(INDEX(IncomeLimits,MATCH($B20,SetAsides,0)),"") -> 0.5 | D20: 2 | E20: =IF(LEN($B20)>1,INDEX(UnitSFAvg,MATCH($A20,UnitTypes,0)),"") -> 1200 | F20: =H20-G20 -> 2481 | G20: =-H70 -> -331 | H20: 2150 | I20: =IFERROR(H20/E20,"") -> 1.7916667 | K20: =IFERROR(H20*12*D20,"") -> 51600 | L20: PBV-LIHTC
A21: 3 BR | B21: =B15 -> 60% PBV | C21: 0.6 | D21: 14 | E21: =IF(LEN($B21)>1,INDEX(UnitSFAvg,MATCH($A21,UnitTypes,0)),"") -> 1200 | F21: =H21-G21 -> 2481 | G21: =-H70 -> -331 | H21: 2150 | I21: =H20/E20 -> 1.7916667 | K21: =IFERROR(H21*12*D21,"") -> 361200 | L21: PBV-LIHTC
A22: 3 BR | B22: =B16 -> 60% LIHTC | C22: =IFERROR(INDEX(IncomeLimits,MATCH($B22,SetAsides,0)),"") -> 0.6 | D22: 10 | E22: =IF(LEN($B22)>1,INDEX(UnitSFAvg,MATCH($A22,UnitTypes,0)),"") -> 1200 | F22: 1577 | G22: =-H70 -> -331 | H22: =IF(SUM(F22:G22)>0,SUM(F22:G22),"") -> 1246 | I22: =IFERROR(H22/E22,"") -> 1.0383333 | K22: =IFERROR(H22*12*D22,"") -> 149520 | L22: LIHTC only
A23: 3 BR | B23: =B17 -> 80% LIHTC | C23: =IFERROR(INDEX(IncomeLimits,MATCH($B23,SetAsides,0)),"") -> 0.8 | D23: 0 | E23: =IF(LEN($B23)>1,INDEX(UnitSFAvg,MATCH($A23,UnitTypes,0)),"") -> 1200 | F23: 2103 | G23: =-H70 -> -331 | H23: =IF(SUM(F23:G23)>0,SUM(F23:G23),"") -> 1772 | I23: =IFERROR(H23/E23,"") -> 1.4766667 | K23: =IFERROR(H23*12*D23,"") -> 0 | L23: LIHTC only
A24: 3 BR | B24: =B18 -> Market | C24: unrestricted | D24: 0 | E24: =IF(LEN($B24)>1,INDEX(UnitSFAvg,MATCH($A24,UnitTypes,0)),"") -> 1200 | F24: 1950 | G24: =IFERROR(IF(INDEX(RentRange,MATCH("UA's",RentRow,0),MATCH($B24,RentColumn,0))="Y", IFERROR(-INDEX(RentRange,MATCH($A24,RentRow,0),MATCH(G$6,RentColumn,0)),""),""),"") | H24: =IF(SUM(F24:G24)>0,SUM(F24:G24),"") -> 1950 | I24: =IFERROR(H24/E24,"") -> 1.625 | K24: =IFERROR(H24*12*D24,"") -> 0 | L24: market
A26: TOTAL | D26: =SUM(D7:D25) -> 221 | E26: =SUMPRODUCT($E$7:$E$25,$D$7:$D$25)/D26 -> 839.93213 | H26: =SUMPRODUCT(K26/12/D26) -> 1404.5973 | K26: =SUM(K7:K25) -> 3724992 | L26: =GrossRentIncomeY1/D26 -> 16855.167 | P26: Target Total Distribution | U26: Actual Distribution by Unit Type
D27: =(D7+D8+D9+D10+D13+D14+D15+D16+D19+D20+D21+D22)/D26 -> 0.95927602 | N27: Distribution of Units | P27: 1 BR | Q27: 2 BR | R27: 3 BR | S27: Total | U27: 1 BR | V27: 2 BR | W27: 3 BR | X27: Total | Y27: Variance
A28: Other Income | F28: Per Unit/Mo. | H28: All Units/Mo. | K28: Annual Revenue | N28: {=IF(SetAsides>0,SetAsides,"")} -> 30% PBV | P28: =P$38*Inputs!$D23 -> 0.047 | Q28: =Q$38*Inputs!$D23 -> 0.041 | R28: =R$38*Inputs!$D23 -> 0.012 | S28: =SUM(P28:R28) -> 0.1 | U28: =C45/TotalUnitCount -> 0.027149321 | V28: =D45/TotalUnitCount -> 0.054298643 | W28: =E45/TotalUnitCount -> 0.0090497738 | X28: =SUM(U28:W28) -> 0.090497738 | Y28: =S28-X28 -> 0.0095022624
A29: Laundry Machine Collections | F29: 0.75 | H29: =F29*TotalUnitCount -> 165.75 | K29: =H29*12 -> 1989 | N29: 50% PBV | P29: =P$38*Inputs!$D24 -> 0.047 | Q29: =Q$38*Inputs!$D24 -> 0.041 | R29: =R$38*Inputs!$D24 -> 0.012 | S29: =SUM(P29:R29) -> 0.1 | U29: =C46/TotalUnitCount -> 0.027149321 | V29: =D46/TotalUnitCount -> 0.054298643 | W29: =E46/TotalUnitCount -> 0.0090497738 | X29: =SUM(U29:W29) -> 0.090497738 | Y29: =S29-X29 -> 0.0095022624
A30: Late Fees | F30: 0.75 | H30: =F30*TotalUnitCount -> 165.75 | K30: =H30*12 -> 1989 | N30: 60% LIHTC | P30: =P$38*Inputs!$D25 -> 0.376 | Q30: =Q$38*Inputs!$D25 -> 0.328 | R30: =R$38*Inputs!$D25 -> 0.096 | S30: =SUM(P30:R30) -> 0.8 | U30: =C48/TotalUnitCount -> 0.11764706 | V30: =D48/TotalUnitCount -> 0.20361991 | W30: =E48/TotalUnitCount -> 0.045248869 | X30: =SUM(U30:W30) -> 0.36651584 | Y30: =S30-X30 -> 0.43348416
A31: Application Fees | F31: 0.75 | H31: =F31*TotalUnitCount -> 165.75 | K31: =H31*12 -> 1989 | N31: 80% LIHTC | P31: =P$38*Inputs!$D26 -> 0 | Q31: =Q$38*Inputs!$D26 -> 0 | R31: =R$38*Inputs!$D26 -> 0 | S31: =SUM(P31:R31) -> 0 | U31: =C49/TotalUnitCount -> 0 | V31: =D49/TotalUnitCount -> 0 | W31: =E49/TotalUnitCount -> 0 | X31: =SUM(U31:W31) -> 0 | Y31: =S31-X31 -> 0
A32: Security Deposit Forfeitures | F32: 0.75 | H32: =F32*TotalUnitCount -> 165.75 | K32: =H32*12 -> 1989 | P32: =P$38*Inputs!$D27 -> 0 | Q32: =Q$38*Inputs!$D27 -> 0 | R32: =R$38*Inputs!$D27 -> 0 | S32: =SUM(P32:R32) -> 0 | U32: =#REF!/TotalUnitCount -> #REF! | V32: =#REF!/TotalUnitCount -> #REF! | W32: =#REF!/TotalUnitCount -> #REF! | X32: =SUM(U32:W32) -> #REF! | Y32: =S32-X32 -> #REF!
A33: Other | F33: 9 | H33: =F33*TotalUnitCount -> 1989 | K33: =H33*12 -> 23868 | M33: =18238/12649-1 -> 0.44185311 | P33: =P$38*Inputs!$D28 -> 0 | Q33: =Q$38*Inputs!$D28 -> 0 | R33: =R$38*Inputs!$D28 -> 0 | S33: =SUM(P33:R33) -> 0 | U33: =#REF!/TotalUnitCount -> #REF! | V33: =#REF!/TotalUnitCount -> #REF! | W33: =#REF!/TotalUnitCount -> #REF! | X33: =SUM(U33:W33) -> #REF! | Y33: =S33-X33 -> #REF!
F34: =SUM(F29:F33) -> 12 | H34: =SUM(H29:H33) -> 2652 | K34: =SUM(K29:K33) -> 31824 | P34: =P$38*Inputs!$D29 -> 0 | Q34: =Q$38*Inputs!$D29 -> 0 | R34: =R$38*Inputs!$D29 -> 0 | S34: =SUM(P34:R34) -> 0 | U34: =#REF!/TotalUnitCount -> #REF! | V34: =#REF!/TotalUnitCount -> #REF! | W34: =#REF!/TotalUnitCount -> #REF! | X34: =SUM(U34:W34) -> #REF! | Y34: =S34-X34 -> #REF!
A35: Commerical Space | E35: SF | H35: Monthly | I35: per SF/mo | J35: per year | K35: Annual Revenue | P35: =P$38*Inputs!$D30 -> 0 | Q35: =Q$38*Inputs!$D30 -> 0 | R35: =R$38*Inputs!$D30 -> 0 | S35: =SUM(P35:R35) -> 0 | U35: =#REF!/TotalUnitCount -> #REF! | V35: =#REF!/TotalUnitCount -> #REF! | W35: =#REF!/TotalUnitCount -> #REF! | X35: =SUM(U35:W35) -> #REF! | Y35: =S35-X35 -> #REF!
A36: Commercial Space | E36: 3000 | H36: 0 | I36: =H36/E36 -> 0 | J36: =I36*12 -> 0 | K36: 100 | P36: =P$38*Inputs!$D31 -> 0 | Q36: =Q$38*Inputs!$D31 -> 0 | R36: =R$38*Inputs!$D31 -> 0 | S36: =SUM(P36:R36) -> 0 | U36: =#REF!/TotalUnitCount -> #REF! | V36: =#REF!/TotalUnitCount -> #REF! | W36: =#REF!/TotalUnitCount -> #REF! | X36: =SUM(U36:W36) -> #REF! | Y36: =S36-X36 -> #REF!
N37: Market | P37: =P$38*Inputs!$D32 -> 0 | Q37: =Q$38*Inputs!$D32 -> 0 | R37: =R$38*Inputs!$D32 -> 0 | S37: =SUM(P37:R37) -> 0 | U37: =C50/TotalUnitCount -> 0.031674208 | V37: =D50/TotalUnitCount -> 0.0090497738 | W37: =E50/TotalUnitCount -> 0 | X37: =SUM(U37:W37) -> 0.040723982 | Y37: =S37-X37 -> -0.040723982
A38: Subsidy Type | C38: Units | D38: Share | H38: Gross Potential Income | K38: =K26 -> 3724992 | N38: Total | P38: =INDEX(unitmix,MATCH(P27,UnitTypes,0)) -> 0.47 | Q38: =INDEX(unitmix,MATCH(Q27,UnitTypes,0)) -> 0.41 | R38: =INDEX(unitmix,MATCH(R27,UnitTypes,0)) -> 0.12 | S38: =SUM(S28:S37) -> 1 | U38: =SUM(U28:U37) -> #REF! | V38: =SUM(V28:V37) -> #REF! | W38: =SUM(W28:W37) -> #REF! | X38: =SUM(X28:X37) -> #REF!
A39: PHA Sec 8 PBV-HAP | C39: =TotalUnitCount-SUM(C40:C41) -> 131 | D39: =C39/$C$42 -> 0.59276018 | H39: Other Income | K39: =AddRevY1 -> 31824
A40: LIHTC | C40: =SUMIF($B$7:$B$25,"*LIHTC",$D$7:$D$25) -> 81 | D40: =C40/$C$42 -> 0.36651584 | H40: Commercial Income per year | K40: =K36 -> 100 | U40: Total LI | X40: =1-X37 -> 0.95927602
A41: Market Rate | C41: =SUMIF($B$7:$B$25,"Market",$D$7:$D$25) -> 9 | D41: =C41/$C$42 -> 0.040723982 | H41: Vacancy | J41: ='20yr Proforma'!J5 -> 0.07 | K41: =SUM(K38:K40)*-J41 -> -262984.12
...

Sheet Operating Expense
A1: OPERATING BUDGET / EXPENSES | M1: ='Summary Sources-Uses'!L2 -> 0
A2: ='Summary Sources-Uses'!A2 -> Project Name | M2: ='Summary Sources-Uses'!L1 -> 45960
N3: NOTE: Expenses updated. Do not match TDHCA application
E5: Independence Heights | J5: Average of Comparable Properties
A6: EXPENSES | E6: ='Rent Schedule'!D26 -> 221 | F6: units | J6: =E6 -> 221 | K6: =F6 -> units
A8: OPERATING EXPENSES | E8: 2024 Baseline | F8: per unit | J8: bad debt | K8: =(H46+J46+L46+N46+P46+R46)/6 -> 193.56109
J9: other admin | K9: =(H47+J47+L47+N47+P47+R47)/6 -> 286.38269
A10: TOTAL ADMINISTRATIVE EXPENSES | E10: =E81 -> 115000 | F10: =E10/$E$6 -> 520.36199 | J10: =K10*E$6 -> 106067.57 | K10: =(H48+J48+L48+N48+P48+R48)/6 -> 479.94378
A11: TOTAL MARKETING EXPENSES | E11: =E86 -> 30000 | F11: =E11/$E$6 -> 135.74661 | J11: =K11*E$6 -> 11241.195 | K11: =(H49+J49+L49+N49+P49+R49)/6 -> 50.865135
A12: TOTAL PAYROLL EXPENSES | E12: =E96 -> 450000 | F12: =E12/$E$6 -> 2036.1991 | J12: =K12*E$6 -> 392076.17 | K12: =(H50+J50+L50+N50+P50+R50)/6 -> 1774.1003
A13: TOTAL MAINTENANCE EXPENSES | E13: =E106 -> 230000 | F13: =E13/$E$6 -> 1040.724 | J13: =K13*E$6 -> 186021.55 | K13: =(H51+J51+L51+N51+P51+R51)/6 -> 841.72646
A14: TOTAL CONTRACT EXPENSES | E14: =E114 -> 210000 | F14: =E14/$E$6 -> 950.22624 | G14: * adjusted for security expense | J14: =K14*E$6 -> 231155.53 | K14: =(H52+J52+L52+N52+P52+R52)/6 -> 1045.9526
A15: TOTAL UTILITY EXPENSES | E15: =E121 -> 215000 | F15: =E15/$E$6 -> 972.85068 | G15: *adjusted for tenant paid utilities | J15: =K15*E$6 -> 152399.68 | K15: =(H53+J53+L53+N53+P53+R53)/6 -> 689.59129
A16: TOTAL MANAGEMENT AND PROFESSIONAL EXPENSES | E16: =E130 -> 361635.91 | F16: =E16/$E$6 -> 1636.3616 | J16: =K16*E$6 -> 279410.3 | K16: =(H54+J54+L54+N54+P54+R54)/6 -> 1264.3
A17: TOTAL TAXES AND INSURANCE | E17: =E136 -> 290000 | F17: =E17/$E$6 -> 1312.2172 | G17: *adjusted for flood insurance where applicable | J17: =K17*E$6 -> 255743.64 | K17: =(H55+J55+L55+N55+P55+R55)/6 -> 1157.211
A18: Annual HHA Issuer Fee | E18: =E138 -> 13562.258 | F18: =E18/$E$6 -> 61.367685
B20: TOTAL EXPENSE | E20: =SUM(E10:E18) -> 1915198.2 | F20: =E20/$E$6 -> 8666.0551 | J20: =SUM(J10:J17) -> 1614115.6 | K20: =SUM(K10:K17) -> 7303.6907
B21: Replacement Reserves | E21: =300*E6 -> 66300 | F21: =E21/$E$6 -> 300
B22: TOTAL EXPENSE + Repl Res. | E22: =E20+E21 -> 1981498.2 | F22: =E22/E6 -> 8966.0551
A24: Property Taxes | E24: 0 | F24: 0 | G24: per unit
A25: W/o Property Taxes or replacement reserves | E25: =E20-E24 -> 1915198.2 | F25: =E25/E6 -> 8666.0551 | G25: per unit
A28: Net Revenue | E28: =NetIncomeY1 -> 3493931.9 | H28: =ExpTotalY1/12 -> 159599.85
A29: Expense Ratio | E29: =E20/E28 -> 0.54814983 | F29: <- may not exceed 65% per TDHCA
A30: NOI/Net Revenue | E30: =(E28-E20)/E28 -> 0.45185017
A33: Columbia Portfolio Family Comps:
A34: Columbia Parc, Renaissance Square, Pendana, Brookside
A37: OPERATING BUDGET / EXPENSES
A38: COMPARABLES in COLUMBIA PORTFOLIO
G40: 2023 Full Year | I40: 2023 Full Year | K40: 2023 Full Year | M40: 2023 Full Year | O40: 2023 Full Year | Q40: 2023 Full Year
G41: Pendana at W Lakes | I41: Columbia Sylvan Hills | K41: Columbia Brookside II-III | M41: Park Commons HFS, HFOP | O41: Renaissance Square | Q41: Columbia Parc @ Bayou Distr
A42: EXPENSES | G42: 200 | H42: units | I42: 191 | J42: units | K42: =132+138 -> 270 | L42: units | M42: =151+179 -> 330 | N42: units | O42: 140 | P42: units | Q42: 466 | R42: units
A44: OPERATING EXPENSES
B46: Bad Debt Expense | G46: 34857.09 | H46: =G46/G$42 -> 174.28545 | I46: 63638.06 | J46: =I46/I$42 -> 333.18356 | K46: =30841.05+17031.96 -> 47873.01 | L46: =K46/K$42 -> 177.30744 | M46: =8259.72+41005.28 -> 49265 | N46: =M46/M$42 -> 149.28788 | O46: 11517.23 | P46: =O46/O$42 -> 82.265929 | Q46: 114186.9 | R46: =Q46/Q$42 -> 245.03627
B47: All Other Admin Expense | G47: =96635.82-G46 -> 61778.73 | H47: =G47/G$42 -> 308.89365 | I47: =115284.62-I46 -> 51646.56 | J47: =I47/I$42 -> 270.40084 | K47: =79427.6-K46+47508.61 -> 79063.2 | L47: =K47/K$42 -> 292.82667 | M47: =50385.39-M46+70545.57 -> 71665.96 | N47: =M47/M$42 -> 217.16958 | O47: =46971.31-O46 -> 35454.08 | P47: =O47/O$42 -> 253.24343 | Q47: =289291.98-Q46 -> 175105.08 | R47: =Q47/Q$42 -> 375.76197
A48: TOTAL ADMINISTRATIVE EXPENSES | G48: =G46+G47 -> 96635.82 | H48: =G48/G$42 -> 483.1791 | I48: =I46+I47 -> 115284.62 | J48: =I48/I$42 -> 603.5844 | K48: =K46+K47 -> 126936.21 | L48: =K48/K$42 -> 470.13411 | M48: =M46+M47 -> 120930.96 | N48: =M48/M$42 -> 366.45745 | O48: =O46+O47 -> 46971.31 | P48: =O48/O$42 -> 335.50936 | Q48: =Q46+Q47 -> 289291.98 | R48: =Q48/Q$42 -> 620.79824
A49: TOTAL MARKETING EXPENSES | G49: 12789.35 | H49: =G49/G$42 -> 63.94675 | I49: 13318.35 | J49: =I49/I$42 -> 69.729581 | K49: =4079.38+3906.67 -> 7986.05 | L49: =K49/K$42 -> 29.577963 | M49: =6019.15+4933.34 -> 10952.49 | N49: =M49/M$42 -> 33.189364 | O49: 7102.73 | P49: =O49/O$42 -> 50.733786 | Q49: 27034.23 | R49: =Q49/Q$42 -> 58.013369
A50: TOTAL PAYROLL EXPENSES | G50: 489458.47 | H50: =G50/G$42 -> 2447.2923 | I50: 347193.89 | J50: =I50/I$42 -> 1817.7691 | K50: =183054.93+193045.46 -> 376100.39 | L50: =K50/K$42 -> 1392.9644 | M50: =285524.83+242835.05 -> 528359.88 | N50: =M50/M$42 -> 1601.0905 | O50: =154648.03+51953 -> 206601.03 | P50: =O50/O$42 -> 1475.7216 | Q50: 889949.97 | R50: =Q50/Q$42 -> 1909.7639
A51: TOTAL MAINTENANCE EXPENSES | G51: 195288.79 | H51: =G51/G$42 -> 976.44395 | I51: 170057.73 | J51: =I51/I$42 -> 890.35461 | K51: =96619.62+106586.17 -> 203205.79 | L51: =K51/K$42 -> 752.61404 | M51: =101093.71+104212.04 -> 205305.75 | N51: =M51/M$42 -> 622.13864 | O51: 121738.49 | P51: =O51/O$42 -> 869.56064 | Q51: 437689.05 | R51: =Q51/Q$42 -> 939.24689
A52: TOTAL CONTRACT EXPENSES | G52: 141629.56 | H52: =G52/G$42 -> 708.1478 | I52: 275639.61 | J52: =I52/I$42 -> 1443.1393 | K52: =158796.88+99845.3 -> 258642.18 | L52: =K52/K$42 -> 957.934 | M52: =197838.2+95082.78 -> 292920.98 | N52: =M52/M$42 -> 887.63933 | O52: =136716.73-51953 -> 84763.73 | P52: =O52/O$42 -> 605.45521 | Q52: 779804.48 | R52: =Q52/Q$42 -> 1673.4002
A53: TOTAL UTILITY EXPENSES | C53: net of water/sewer collection | G53: =210123.7-82110.95 -> 128012.75 | H53: =G53/G$42 -> 640.06375 | I53: =310145.67-168748.08 -> 141397.59 | J53: =I53/I$42 -> 740.30152 | K53: =143111.58-73181.92-77139.45+131485.39 -> 124275.6 | L53: =K53/K$42 -> 460.28 | M53: =362149.68+138733.19 -> 500882.87 | N53: =M53/M$42 -> 1517.8269 | O53: =66341.65-22450 -> 43891.65 | P53: =O53/O$42 -> 313.51179 | Q53: =216952.74 -> 216952.74 | R53: =Q53/Q$42 -> 465.56382
...

Sheet 20yr Proforma
A1: SUMMARY PROFORMA | D1: ='Summary Sources-Uses'!L1 -> 45960
A2: Development Name: | F2: ='Summary Sources-Uses'!A2 -> Project Name | K2: ='Summary Sources-Uses'!L1 -> 45960
C4: Year | F4: 1 | G4: 2 | H4: 3 | I4: 4 | J4: 5 | K4: 6 | L4: 7 | M4: 8 | N4: 9 | O4: 10 | P4: 11 | Q4: 12 | R4: 13 | S4: 14 | T4: 15
A5: Units: | C5: =TotalUnitCount -> 221 | F5: Annual Income Growth Rate: | H5: =RevInfl -> 0.02 | I5: Vacancy Loss | J5: 0.07 | K5: Annual Operating Expense/unit | M5: ='Operating Expense'!F20 -> 8666.0551 | N5: * on sqr. foot basis | O5: LP Investor Asset Mgmt Fee: | Q5: 8500 | R5: fee increases 3% per annum
A6: Total Rentable SF: | C6: ='Rent Schedule'!E26*'Rent Schedule'!D26 -> 185625 | F6: Annual Expense Growth Rate: | H6: 0.03 | K6: Annual Replacement Reserve/unit | M6: =ReplReserve -> 300 | O6: Other Asset Mgmt. Fee: | Q6: 7500 | R6: fee increases 3% per annum
A7: Stabilized Year 1 = | C7: 2028 | M7: =M5+M6 -> 8966.0551 | O7: SLP Asset Mgt fee | Q7: 7500 | R7: fee increases 3% per annum
E9: 2025 | F9: =$C$4&" "&F4 -> Year 1 | G9: =$C$4&" "&G4 -> Year 2 | H9: =$C$4&" "&H4 -> Year 3 | I9: =$C$4&" "&I4 -> Year 4 | J9: =$C$4&" "&J4 -> Year 5 | K9: =$C$4&" "&K4 -> Year 6 | L9: =$C$4&" "&L4 -> Year 7 | M9: =$C$4&" "&M4 -> Year 8 | ... T9: =$C$4&" "&T4 -> Year 15 | U9: Year 16 | V9: Year 17 | W9: Year 18 | X9: Year 19 | Y9: Year 20
E10: baseline | F10: 2028 | G10: =F10+1 -> 2029 | H10: =G10+1 -> 2030 | I10: =H10+1 -> 2031 | J10: =I10+1 -> 2032 | K10: =J10+1 -> 2033 | L10: =K10+1 -> 2034 | M10: =L10+1 -> 2035 | N10: =M10+1 -> 2036 | ... Y10: =X10+1 -> 2047
E11: * note that rents/expenses are trended from current levels | F11: 1 | G11: 2 | H11: 3 | I11: 4 | J11: 5 | K11: 6 | L11: 7 | M11: 8 | N11: 9 | O11: 10 | P11: 11 | Q11: 12 | R11: 13 | S11: 14 | T11: 15 | U11: 16 | V11: 17 | W11: 18 | X11: 19 | Y11: 20
A12: Total Potential Rent Income | E12: =GrossRentIncomeY1 -> 3724992 | F12: =E12 -> 3724992 | G12: =F12*(1+$H5) -> 3799491.8 | H12: =G12*(1+$H5) -> 3875481.7 | I12: =H12*(1+$H5) -> 3952991.3 | J12: =I12*(1+$H5) -> 4032051.1 | K12: =J12*(1+$H5) -> 4112692.2 | L12: =K12*(1+$H5) -> 4194946 | M12: =L12*(1+$H5) -> 4278844.9 | N12: =M12*(1+$H5) -> 4364421.8 | ... Y12: =X12*(1+$H5) -> 5426610
A13: ADD: | B13: Commercial + Other Income | E13: =AddRevY1+'Rent Schedule'!K36 -> 31924 | F13: =E13 -> 31924 | G13: =F13*(1+$H5) -> 32562.48 | H13: =G13*(1+$H5) -> 33213.73 | I13: =H13*(1+$H5) -> 33878.004 | J13: =I13*(1+$H5) -> 34555.564 | K13: =J13*(1+$H5) -> 35246.676 | L13: =K13*(1+$H5) -> 35951.609 | M13: =L13*(1+$H5) -> 36670.641 | N13: =M13*(1+$H5) -> 37404.054 | ... Y13: =X13*(1+$H5) -> 46507.24
A15: Gross Potential Income | E15: =E12+E13 -> 3756916 | F15: =F12+F13 -> 3756916 | G15: =G12+G13 -> 3832054.3 | H15: =H12+H13 -> 3908695.4 | I15: =I12+I13 -> 3986869.3 | J15: =J12+J13 -> 4066606.7 | K15: =K12+K13 -> 4147938.8 | L15: =L12+L13 -> 4230897.6 | ... Y15: =Y12+Y13 -> 5473117.2
A17: LESS: | B17: Vacancy Allowance/Bad Debts/Concessions | E17: =(E12+E13)*$J5 -> 262984.12 | F17: =(F12+F13)*$J5 -> 262984.12 | G17: =(G12+G13)*$J5 -> 268243.8 | H17: =(H12+H13)*$J5 -> 273608.68 | I17: =(I12+I13)*$J5 -> 279080.85 | J17: =(J12+J13)*$J5 -> 284662.47 | K17: =(K12+K13)*$J5 -> 290355.72 | L17: =(L12+L13)*$J5 -> 296162.83 | ... Y17: =(Y12+Y13)*$J5 -> 383118.2
A19: Stabilized Income | E19: =+E15-E17 -> 3493931.9 | F19: =+F15-F17 -> 3493931.9 | G19: =+G15-G17 -> 3563810.5 | H19: =+H15-H17 -> 3635086.7 | I19: =+I15-I17 -> 3707788.5 | J19: =+J15-J17 -> 3781944.2 | K19: =+K15-K17 -> 3857583.1 | L19: =+L15-L17 -> 3934734.8 | ... Y19: =+Y15-Y17 -> 5089999
A21: LESS: | B21: Operating Expenses | E21: =ExpTotalY1 -> 1915198.2 | F21: =E21 -> 1915198.2 | G21: =$F21*(1+$H6)^(G11-1) -> 1972654.1 | H21: =$F21*(1+$H6)^(H11-1) -> 2031833.7 | I21: =$F21*(1+$H6)^(I11-1) -> 2092788.8 | J21: =$F21*(1+$H6)^(J11-1) -> 2155572.4 | K21: =$F21*(1+$H6)^(K11-1) -> 2220239.6 | L21: =$F21*(1+$H6)^(L11-1) -> 2286846.8 | M21: =$F21*(1+$H6)^(M11-1) -> 2355452.2 | N21: =$F21*(1+$H6)^(N11-1) -> 2426115.7 | ... Y21: =$F21*(1+$H6)^(Y11-1) -> 3358311.6
A22: ADD: Property Tax Reduction | D22: =IF(Inputs!M25>0,"yes","no") -> yes | E22: =-'Operating Expense'!E24 -> 0 | F22: =$E$22*(1+$H$6)^F11*INDEX(Inputs!$M$25:$M$39,MATCH('20yr Proforma'!F11,Inputs!$L$25:$L$39,0)) -> 0 | G22: =$E$22*(1+$H$6)^G11*INDEX(Inputs!$M$25:$M$39,MATCH('20yr Proforma'!G11,Inputs!$L$25:$L$39,0)) -> 0 | H22: =$E$22*(1+$H$6)^H11*INDEX(Inputs!$M$25:$M$39,MATCH('20yr Proforma'!H11,Inputs!$L$25:$L$39,0)) -> 0 | I22: =$E$22*(1+$H$6)^I11*INDEX(Inputs!$M$25:$M$39,MATCH('20yr Proforma'!I11,Inputs!$L$25:$L$39,0)) -> 0 | J22: =$E$22*(1+$H$6)^J11*INDEX(Inputs!$M$25:$M$39,MATCH('20yr Proforma'!J11,Inputs!$L$25:$L$39,0)) -> 0 | K22: =$E$22*(1+$H$6)^K11*INDEX(Inputs!$M$25:$M$39,MATCH('20yr Proforma'!K11,Inputs!$L$25:$L$39,0)) -> 0 | L22: =$E$22*(1+$H$6)^L11*INDEX(Inputs!$M$25:$M$39,MATCH('20yr Proforma'!L11,Inputs!$L$25:$L$39,0)) -> 0 | M22: =$E$22*(1+$H$6)^M11*INDEX(Inputs!$M$25:$M$39,MATCH('20yr Proforma'!M11,Inputs!$L$25:$L$39,0)) -> 0 | ... T22: =$E$22*(1+$H$6)^T11*INDEX(Inputs!$M$25:$M$39,MATCH('20yr Proforma'!T11,Inputs!$L$25:$L$39,0)) -> 0 | U22: =$E$22*(1+$H$6)^U11*INDEX(Inputs!$M$25:$M$45,MATCH('20yr Proforma'!U11,Inputs!$L$25:$L$45,0)) -> 0 | V22: =$E$22*(1+$H$6)^V11*INDEX(Inputs!$M$25:$M$45,MATCH('20yr Proforma'!V11,Inputs!$L$25:$L$45,0)) -> 0 | W22: =$E$22*(1+$H$6)^W11*INDEX(Inputs!$M$25:$M$45,MATCH('20yr Proforma'!W11,Inputs!$L$25:$L$45,0)) -> 0 | X22: =$E$22*(1+$H$6)^X11*INDEX(Inputs!$M$25:$M$45,MATCH('20yr Proforma'!X11,Inputs!$L$25:$L$45,0)) -> 0 | Y22: =$E$22*(1+$H$6)^Y11*INDEX(Inputs!$M$25:$M$45,MATCH('20yr Proforma'!Y11,Inputs!$L$25:$L$45,0)) -> 0
A23: LESS: | B23: Replacement Reserves | E23: =F23 -> 66300 | F23: =M6*$C5 -> 66300 | G23: =F23*(1+$H6) -> 68289 | H23: =G23*(1+$H6) -> 70337.67 | I23: =H23*(1+$H6) -> 72447.8 | J23: =I23*(1+$H6) -> 74621.234 | K23: =J23*(1+$H6) -> 76859.871 | L23: =K23*(1+$H6) -> 79165.667 | M23: =L23*(1+$H6) -> 81540.637 | N23: =M23*(1+$H6) -> 83986.856 | ... Y23: =X23*(1+$H6) -> 116257.45
A24: Net Operating Income | E24: =E19-E21-E23-E22 -> 1512433.7 | F24: =F19-F21-F23-F22 -> 1512433.7 | G24: =G19-G21-G23-G22 -> 1522867.4 | H24: =H19-H21-H23-H22 -> 1532915.3 | I24: =I19-I21-I23-I22 -> 1542551.9 | J24: =J19-J21-J23-J22 -> 1551750.6 | K24: =K19-K21-K23-K22 -> 1560483.7 | L24: =L19-L21-L23-L22 -> 1568722.3 | ... Y24: =Y19-Y21-Y23-Y22 -> 1615430
B26: SCHEDULED DEBT SERVICE:
A27: LESS: | B27: Debt Service 1st | E27: ='[5]Summary Sources-Uses'!$D$8 -> 1st Mortgage | F27: ='Summary Sources-Uses'!L49 -> 0 | G27: =F27 -> 0 | H27: =G27 -> 0 | I27: =H27 -> 0 | J27: =I27 -> 0 | K27: =J27 -> 0 | L27: =K27 -> 0 | M27: =L27 -> 0 | N27: =M27 -> 0 | ... Y27: =X27 -> 0
B28: Debt Service 2nd | E28: ='Summary Sources-Uses'!E53 -> GAP Funding (TBD) | F28: ='Summary Sources-Uses'!L53 -> 0 | G28: =F28 -> 0 | H28: =G28 -> 0 | I28: =H28 -> 0 | J28: =I28 -> 0 | K28: =J28 -> 0 | L28: =K28 -> 0 | M28: =L28 -> 0 | N28: =M28 -> 0 | ... Y28: =X28 -> 0
B29: Debt Service 3rd | E29: ='Summary Sources-Uses'!E55 -> 0 | F29: ='Summary Sources-Uses'!L55 -> 0 | G29: =F29 -> 0 | H29: =G29 -> 0 | I29: =H29 -> 0 | J29: =I29 -> 0 | K29: =J29 -> 0 | L29: =K29 -> 0 | M29: =L29 -> 0 | N29: =M29 -> 0 | ... Y29: =X29 -> 0
B30: Debt Service 4th | F30: ='Summary Sources-Uses'!L57 -> 0 | G30: =F30 -> 0 | H30: =G30 -> 0 | I30: =H30 -> 0 | J30: =I30 -> 0 | K30: =J30 -> 0 | L30: =K30 -> 0 | M30: =L30 -> 0 | N30: =M30 -> 0 | ... Y30: =X30 -> 0
B31: Debt Service 5th
B32: Debt Service 6th
C33: deferred fee note | E33: 12 | F33: =MIN(F63,SUM(F39:F41)) -> -18830917 | G33: =MIN(G63,SUM(G39:G41)) -> 0 | H33: =MIN(H63,SUM(H39:H41)) -> 0 | I33: =MIN(I63,SUM(I39:I41)) -> 0 | J33: =MIN(J63,SUM(J39:J41)) -> 0 | K33: =MIN(K63,SUM(K39:K41)) -> 0 | L33: =MIN(L63,SUM(L39:L41)) -> 0 | M33: =MIN(M63,SUM(M39:M41)) -> 0 | ... T33: =MIN(T63,SUM(T39:T41)) -> 0
A35: Operating Cash Flow Waterfall:
B36: Net Operating Income: | F36: =F24 -> 1512433.7 | G36: =G24 -> 1522867.4 | H36: =H24 -> 1532915.3 | I36: =I24 -> 1542551.9 | J36: =J24 -> 1551750.6 | K36: =K24 -> 1560483.7 | L36: =L24 -> 1568722.3 | M36: =M24 -> 1576436.7 | ... Y36: =Y24 -> 1615430
B37: (less) First mortgage debt | E37: scheduled P&I | F37: =-F27 -> 0 | G37: =-G27 -> 0 | H37: =-H27 -> 0 | I37: =-I27 -> 0 | J37: =-J27 -> 0 | K37: =-K27 -> 0 | L37: =-L27 -> 0 | M37: =-M27 -> 0 | ... Y37: =-Y27 -> 0
B38: (less) Second mortgage debt_HHA | F38: =-'Summary Sources-Uses'!L51 -> 0 | G38: =F38 -> 0 | H38: =G38 -> 0 | I38: =H38 -> 0 | J38: =I38 -> 0 | K38: =J38 -> 0 | L38: =K38 -> 0 | M38: =L38 -> 0 | N38: =M38 -> 0 | ... Y38: =X38 -> 0
B39: Cash Flow after 1st Mortg Debt: | F39: =SUM(F36:F38) -> 286024.76 | G39: =SUM(G36:G38) -> 296458.45 | H39: =SUM(H36:H38) -> 306506.37 | I39: =SUM(I36:I38) -> 316142.96 | J39: =SUM(J36:J38) -> 325341.63 | K39: =SUM(K36:K38) -> 334074.71 | L39: =SUM(L36:L38) -> 342313.39 | M39: =SUM(M36:M38) -> 350027.71 | ... Y39: =SUM(Y36:Y38) -> 389021.01
B41: (less) Investor LP Asset Mgmt fee | E41: from cash flow | F41: =-$Q$5 -> -8500 | G41: =F41*(1+$H6) -> -8755 | H41: =G41*(1+$H6) -> -9017.65 | I41: =H41*(1+$H6) -> -9288.1795 | J41: =I41*(1+$H6) -> -9566.8249 | K41: =J41*(1+$H6) -> -9853.8296 | L41: =K41*(1+$H6) -> -10149.445 | M41: =L41*(1+$H6) -> -10453.928 | N41: =M41*(1+$H6) -> -10767.546 | ... Y41: =X41*(1+$H6) -> -14904.801
B42: (less) payment to DDF | E42: from cash flow -to P&I | F42: =-F33 -> 18830917 | G42: =-MIN(SUM(G39:G41),G63) -> 0 | H42: =-MIN(SUM(H39:H41),H63) -> 0 | I42: =-MIN(SUM(I39:I41),I63) -> 0 | J42: =-MIN(SUM(J39:J41),J63) -> 0 | K42: =-MIN(SUM(K39:K41),K63) -> 0 | L42: =-MIN(SUM(L39:L41),L63) -> 0 | M42: =-MIN(SUM(M39:M41),M63) -> 0 | N42: =-MIN(SUM(N39:N41),N63) -> 0 | ... T42: =-MIN(SUM(T39:T41),T63) -> 0 | U42: 0 | V42: 0 | W42: 0 | X42: 0 | Y42: 0
B43: (less) SLP Asset Mgmt fee-Columbia SLP | E43: from cash flow | F43: =IF(SUM(F39:F42)>F83, -F83,0) -> -8500 | G43: =IF(SUM(G39:G42)>G83, -G83,0) -> -8755 | H43: =IF(SUM(H39:H42)>H83, -H83,0) -> -9017.65 | I43: =IF(SUM(I39:I42)>I83, -I83,0) -> -9288.1795 | J43: =IF(SUM(J39:J42)>J83, -J83,0) -> -9566.8249 | K43: =IF(SUM(K39:K42)>K83, -K83,0) -> -9853.8296 | L43: =IF(SUM(L39:L42)>L83, -L83,0) -> -10149.445 | M43: =IF(SUM(M39:M42)>M83, -M83,0) -> -10453.928 | ... Y43: =IF(SUM(Y39:Y42)>Y83, -Y83,0) -> -14904.801
B44: (less) Cash Flow to Investor LP | D44: 0.1 | E44: from cash flow | F44: =IF(SUM(F39:F43)>0,-SUM(F39:F43)*$D$44,0) -> -1909994.1 | G44: =IF(SUM(G39:G43)>0,-SUM(G39:G43)*$D$44,0) -> -27894.845 | H44: =IF(SUM(H39:H43)>0,-SUM(H39:H43)*$D$44,0) -> -28847.107 | I44: =IF(SUM(I39:I43)>0,-SUM(I39:I43)*$D$44,0) -> -29756.66 | J44: =IF(SUM(J39:J43)>0,-SUM(J39:J43)*$D$44,0) -> -30620.798 | K44: =IF(SUM(K39:K43)>0,-SUM(K39:K43)*$D$44,0) -> -31436.705 | L44: =IF(SUM(L39:L43)>0,-SUM(L39:L43)*$D$44,0) -> -32201.45 | M44: =IF(SUM(M39:M43)>0,-SUM(M39:M43)*$D$44,0) -> -32911.985 | ... Y44: =IF(SUM(Y39:Y43)>0,-SUM(Y39:Y43)*$D$44,0) -> -35921.141
B45: (less) Cashflow to GP/SLP | D45: 0.0001 | E45: from cash flow | F45: =IF(SUM(F39:F43)>0,-SUM(F39:F43)*$D$45,0) -> -1909.9941 | G45: =IF(SUM(G39:G43)>0,-SUM(G39:G43)*$D$45,0) -> -27.894845 | H45: =IF(SUM(H39:H43)>0,-SUM(H39:H43)*$D$45,0) -> -28.847107 | I45: =IF(SUM(I39:I43)>0,-SUM(I39:I43)*$D$45,0) -> -29.75666 | J45: =IF(SUM(J39:J43)>0,-SUM(J39:J43)*$D$45,0) -> -30.620798 | K45: =IF(SUM(K39:K43)>0,-SUM(K39:K43)*$D$45,0) -> -31.436705 | L45: =IF(SUM(L39:L43)>0,-SUM(L39:L43)*$D$45,0) -> -32.20145 | M45: =IF(SUM(M39:M43)>0,-SUM(M39:M43)*$D$45,0) -> -32.911985 | ... Y45: =IF(SUM(Y39:Y43)>0,-SUM(Y39:Y43)*$D$45,0) -> -35.921141
B46: (less) Incentive Mgmt Fee to GP/SLP | D46: 0.9 | E46: from cash flow | F46: =-F89 -> -201135.91 | G46: =-G89 -> -205073.63 | H46: =-H89 -> -209087.55 | I46: =-I89 -> -213179.13 | J46: =-J89 -> -217349.83 | K46: =-K89 -> -221601.16 | L46: =-L89 -> -225934.64 | M46: =-M89 -> -230351.84 | ... Y46: =-Y89 -> -290495.14
B47: (less) 2nd mortgage debt-HHA | D47: 0.5 | E47: from cash flow -to P&I | F47: =IF(SUM(F39:F46)>0,-SUM(F39:F46)*$D$47,0) -> -8493450.7 | G47: =IF(SUM(G39:G46)>0,-SUM(G39:G46)*$D$47,0) -> -22976.04 | H47: =IF(SUM(H39:H46)>0,-SUM(H39:H46)*$D$47,0) -> -25253.781 | I47: =IF(SUM(I39:I46)>0,-SUM(I39:I46)*$D$47,0) -> -27300.529 | J47: =IF(SUM(J39:J46)>0,-SUM(J39:J46)*$D$47,0) -> -29103.368 | K47: =IF(SUM(K39:K46)>0,-SUM(K39:K46)*$D$47,0) -> -30648.875 | L47: =IF(SUM(L39:L46)>0,-SUM(L39:L46)*$D$47,0) -> -31923.103 | M47: =IF(SUM(M39:M46)>0,-SUM(M39:M46)*$D$47,0) -> -32911.558 | ... Y47: =IF(SUM(Y39:Y46)>0,-SUM(Y39:Y46)*$D$47,0) -> -16379.604
B48: (less) | D48: 0.5 | E48: from cash flow -to P&I | F48: =-IF(SUM(F$39:F47)>0,MIN(F29,SUM(F$39:F47)*$D$48),0) -> 0 | G48: =-IF(SUM(G$39:G47)>0,MIN(G29,SUM(G$39:G47)*$D$48),0) -> 0 | H48: =-IF(SUM(H$39:H47)>0,MIN(H29,SUM(H$39:H47)*$D$48),0) -> 0 | I48: =-IF(SUM(I$39:I47)>0,MIN(I29,SUM(I$39:I47)*$D$48),0) -> 0 | J48: =-IF(SUM(J$39:J47)>0,MIN(J29,SUM(J$39:J47)*$D$48),0) -> 0 | K48: =-IF(SUM(K$39:K47)>0,MIN(K29,SUM(K$39:K47)*$D$48),0) -> 0 | L48: =-IF(SUM(L$39:L47)>0,MIN(L29,SUM(L$39:L47)*$D$48),0) -> 0 | M48: =-IF(SUM(M$39:M47)>0,MIN(M29,SUM(M$39:M47)*$D$48),0) -> 0 | ... Y48: =-IF(SUM(Y$39:Y47)>0,MIN(Y29,SUM(Y$39:Y47)*$D$48),0) -> 0
B49: Net Cash Flow | F49: =SUM(F39:F48) -> 8493450.7 | G49: =SUM(G39:G48) -> 22976.04 | H49: =SUM(H39:H48) -> 25253.781 | I49: =SUM(I39:I48) -> 27300.529 | J49: =SUM(J39:J48) -> 29103.368 | K49: =SUM(K39:K48) -> 30648.875 | L49: =SUM(L39:L48) -> 31923.103 | M49: =SUM(M39:M48) -> 32911.558 | ... Y49: =SUM(Y39:Y48) -> 16379.604
...

Sheet Credit Delivery & Pay-Ins
B1: ='Summary Sources-Uses'!A2 -> Project Name | G1: ='Summary Sources-Uses'!L2 -> 0 | Q1: ='Summary Sources-Uses'!L1 -> 45960
C3: Credit Allocation (annual): | F3: ='Summary Sources-Uses'!E37 -> 946178.12 | J3: Annual Credits (allocation): | N3: =F3 -> 946178.12 | P3: Closing | Q3: ='Flow of Funds'!H3 -> 46447
C4: Total Units: | F4: =TotalUnitCount -> 221 | J4: Syndicator Percentage: | N4: 0.9999 | P4: Construction | Q4: 22
C5: LIHTC Units: | F5: 212 | J5: Equity Pricing (per credit): | N5: ='Summary Sources-Uses'!D38 -> 0.87 | P5: Completion | Q5: =EDATE(Q3,Q4) -> 47119
C6: Cred Factor | F6: =(F3/F5)/12*N4 -> 371.88817
K7: Total Equity Pay-In | N7: ='Summary Sources-Uses'!E39 -> 8230926.5 | P7: Absorbtion Rate | Q7: 25
B8: LEASE-UP / CREDIT DELIVERY SCHEDULE
C9: LIHTC Units Only
B10: Year | C10: Units Leased | D10: Cumulative | E10: Tax Credit | F10: Monthly | I10: EQUITY PAY-IN SCHEDULE
B11: =YEAR(Q5) -> 2029 | C11: In Month | D11: Leased | E11: Factor | F11: Credits | K11: Month | L11: Milestone | M11: % complete | N11: Federal | O11: State | P11: total | Q11: % of total
B12: January | C12: 0 | D12: =C12 -> 0 | E12: 0 | F12: =D12*E12 -> 0 | H12: =DATE(I12,1,1) -> 45658 | I12: 2025 | J12: January
B13: February | C13: 0 | D13: =D12+C13 -> 0 | E13: 0 | F13: =D13*E13 -> 0 | H13: =EDATE(H12,1) -> 45689 | J13: February
B14: March | C14: 0 | D14: =D13+C14 -> 0 | E14: 0 | F14: =D14*E14 -> 0 | H14: =EDATE(H13,1) -> 45717 | J14: March
B15: April | C15: 0 | D15: =D14+C15 -> 0 | E15: 0 | F15: =D15*E15 -> 0 | H15: =EDATE(H14,1) -> 45748 | J15: April
B16: May | C16: 0 | D16: =D15+C16 -> 0 | E16: 0 | F16: =D16*E16 -> 0 | H16: =EDATE(H15,1) -> 45778 | J16: May
B17: June | C17: 0 | D17: =D16+C17 -> 0 | E17: 0 | F17: =D17*E17 -> 0 | H17: =EDATE(H16,1) -> 45809 | J17: June
B18: July | C18: 0 | D18: =D17+C18 -> 0 | E18: 0 | F18: =D18*E18 -> 0 | H18: =EDATE(H17,1) -> 45839 | J18: July
B19: August | C19: 0 | D19: =D18+C19 -> 0 | E19: 0 | F19: =D19*E19 -> 0 | H19: =EDATE(H18,1) -> 45870 | J19: August
B20: September | C20: 6 | D20: =D19+C20 -> 6 | E20: 0 | F20: =D20*E20 -> 0 | H20: =EDATE(H19,1) -> 45901 | J20: September
B21: October | C21: 10 | D21: =D20+C21 -> 16 | E21: 0 | F21: =D21*E21 -> 0 | H21: =EDATE(H20,1) -> 45931 | J21: October
B22: November | C22: 15 | D22: =D21+C22 -> 31 | E22: 0 | F22: =D22*E22 -> 0 | H22: =EDATE(H21,1) -> 45962 | J22: November | K22: 0 | L22: CLOSING | N22: =$N$7*Q22 -> 823092.65 | Q22: 0.1 | S22: 0.1
B23: December | C23: 20 | D23: =D22+C23 -> 51 | E23: 0 | F23: =D23*E23 -> 0 | H23: =EDATE(H22,1) -> 45992 | J23: December | K23: =K22+1 -> 1
B24: Totals: | C24: =SUM(C12:C23) -> 51 | D24: =D23 -> 51 | F24: =SUM(F20:F23) -> 0 | H24: =EDATE(H23,1) -> 46023 | I24: =I12+1 -> 2026 | J24: January | K24: =K23+1 -> 2
H25: =EDATE(H24,1) -> 46054 | J25: February | K25: =K24+1 -> 3
H26: =EDATE(H25,1) -> 46082 | J26: March | K26: =K25+1 -> 4
B27: Year | C27: Units Leased | D27: Cumulative | E27: Tax Credit | F27: Monthly | H27: =EDATE(H26,1) -> 46113 | J27: April | K27: =K26+1 -> 5
B28: =B11+1 -> 2030 | C28: In Month | D28: Leased | E28: Factor | F28: Credits | H28: =EDATE(H27,1) -> 46143 | J28: May | K28: =K27+1 -> 6
B29: January | C29: 20 | D29: =D23+C29 -> 71 | E29: =F$6 -> 371.88817 | F29: =D29*E29 -> 26404.06 | H29: =EDATE(H28,1) -> 46174 | J29: June | K29: =K28+1 -> 7
B30: February | C30: 25 | D30: =D29+C30 -> 96 | E30: =F$6 -> 371.88817 | F30: =D30*E30 -> 35701.264 | H30: =EDATE(H29,1) -> 46204 | J30: July | K30: =K29+1 -> 8
B31: March | C31: =MIN($F$5-SUM($C$24,$C$29:C30),$Q$7) -> 25 | D31: =D30+C31 -> 121 | E31: =F$6 -> 371.88817 | F31: =D31*E31 -> 44998.469 | H31: =EDATE(H30,1) -> 46235 | J31: August | K31: =K30+1 -> 9
B32: April | C32: =MIN($F$5-SUM($C$24,$C$29:C31),$Q$7) -> 25 | D32: =D31+C32 -> 146 | E32: =F$6 -> 371.88817 | F32: =D32*E32 -> 54295.673 | H32: =EDATE(H31,1) -> 46266 | J32: September | K32: =K31+1 -> 10
B33: May | C33: =MIN($F$5-SUM($C$24,$C$29:C32),$Q$7) -> 25 | D33: =D32+C33 -> 171 | E33: =F$6 -> 371.88817 | F33: =D33*E33 -> 63592.877 | H33: =EDATE(H32,1) -> 46296 | J33: October | K33: =K32+1 -> 11 | L33: 50% complete | N33: =N10*Q33 -> 0 | Q33: 0
B34: June | C34: 25 | D34: =D33+C34 -> 196 | E34: =F$6 -> 371.88817 | F34: =D34*E34 -> 72890.081 | H34: =EDATE(H33,1) -> 46327 | J34: November | K34: =K33+1 -> 12
B35: July | C35: 25 | D35: =D34+C35 -> 221 | E35: =F$6 -> 371.88817 | F35: =D35*E35 -> 82187.286 | H35: =EDATE(H34,1) -> 46357 | J35: December | K35: =K34+1 -> 13
B36: August | C36: 0 | D36: =D35+C36 -> 221 | E36: =F$6 -> 371.88817 | F36: =D36*E36 -> 82187.286 | H36: =EDATE(H35,1) -> 46388 | I36: =I24+1 -> 2027 | J36: January | K36: =K35+1 -> 14
B37: September | C37: 0 | D37: =D36+C37 -> 221 | E37: =F$6 -> 371.88817 | F37: =D37*E37 -> 82187.286 | H37: =EDATE(H36,1) -> 46419 | J37: February | K37: =K36+1 -> 15
B38: October | C38: 0 | D38: =D37+C38 -> 221 | E38: =F$6 -> 371.88817 | F38: =D38*E38 -> 82187.286 | H38: =EDATE(H37,1) -> 46447 | J38: March | K38: =K37+1 -> 16
B39: November | C39: 0 | D39: =D38+C39 -> 221 | E39: =F$6 -> 371.88817 | F39: =D39*E39 -> 82187.286 | H39: =EDATE(H38,1) -> 46478 | J39: April | K39: =K38+1 -> 17
B40: December | C40: 0 | D40: =D39+C40 -> 221 | E40: =F$6 -> 371.88817 | F40: =D40*E40 -> 82187.286 | H40: =EDATE(H39,1) -> 46508 | J40: May | K40: =K39+1 -> 18
B41: Totals: | C41: =SUM(C29:C40) -> 170 | D41: =D40 -> 221 | F41: =SUM(F29:F40) -> 791006.14 | H41: =EDATE(H40,1) -> 46539 | J41: June | K41: =K40+1 -> 19
...

Sheet Flow of Funds
B1: FLOW OF FUNDS | F1: ='Summary Sources-Uses'!L1 -> 45960 | G1: ='Summary Sources-Uses'!L2 -> 0
B2: ='Summary Sources-Uses'!A2 -> Project Name | H2: 0 | I2: 1 | J2: =I2+1 -> 2 | K2: =J2+1 -> 3 | L2: =K2+1 -> 4 | M2: =L2+1 -> 5 | N2: =M2+1 -> 6 | O2: =N2+1 -> 7 | P2: =O2+1 -> 8 | Q2: =P2+1 -> 9 | ... AU2: =AT2+1 -> 39
B3: ='Summary Sources-Uses'!L3 -> 0 Family Units | H3: 46447 | I3: =EDATE(H3,1) -> 46478 | J3: =EDATE(I3,1) -> 46508 | K3: =EDATE(J3,1) -> 46539 | L3: =EDATE(K3,1) -> 46569 | M3: =EDATE(L3,1) -> 46600 | N3: =EDATE(M3,1) -> 46631 | O3: =EDATE(N3,1) -> 46661 | P3: =EDATE(O3,1) -> 46692 | ... AU3: =EDATE(AT3,1) -> 47635
F4: Total | G4: Expended | H4: Closing | I4: Construction Start----------> | S4: 50% Completion | AD4: 100% Complete | AE4: Constr Completion | AR4: Stabilization | AV4: Total Drawn | AW4: Variance
A5: SOURCES | AD5: 2nd Installment | AE5: 2nd Installment | AR5: 3rd Installment
B6: Tax Exempt Bonds | F6: ='Summary Sources-Uses'!K67 -> 13562258 | H6: =F6 -> 13562258
B7: ='Summary Sources-Uses'!E68 -> Construction Loan (Taxable) | F7: ='Summary Sources-Uses'!K68 -> -1762837.9 | H7: =H103-H10-H11 -> 2364554.4 | I7: =I103-I13 -> -103667.16 | J7: 0 | K7: 0 | L7: 0 | M7: =M103-M10-M13 -> 300377.8 | N7: =N103-N13 -> 834406.43 | O7: =O103-O10-O13 -> 668617.86 | P7: 0 | Q7: =Q103-Q10-Q13 -> 737699.64 | R7: =R103-R9-R13 -> 991730.41 | T7: =T103-T10-T13 -> 209939.81 | U7: =U103-U13 -> 975839.6 | V7: =V103-V10-V13 -> 691434.96 | X7: =X103-X10-X13 -> -16927970 | Y7: =Y103-Y13 -> 859741.88 | Z7: =Z103-Z13 -> 854470.46 | AA7: =AA103-AA13 -> 922170.05 | AB7: =AB103-AB13 -> 812241.98 | AC7: =AC103-AC13 -> 766709.31 | AD7: =AD103-AD13 -> 3278864.6 | AE7: =(AE103-AE11-AE13) -> 10379008 | AO7: =AO103-AO11-AO13 -> 47388.938 | AP7: =AP103-AP11-AP13 -> 47649.577 | AQ7: =AQ103-AQ11-AQ13 -> 47911.65 | AR7: =-SUM(H7:AQ7) -> -8759120.7 | AV7: =SUM(H7:AU7) -> 0 | AW7: =F7-AV7 -> -1762837.9
B8: First Mortgage (Freddie TEL) | D8: =F8/F$16 -> 0.46441928 | F8: ='Summary Sources-Uses'!E8 -> 0 | AR8: =F8 -> 0 | AV8: =SUM(H8:AU8) -> 0 | AW8: =F8-AV8 -> 0
B9: 2nd Mortgage (HHA Funds) | D9: =F9/F$16 -> 0.09136117 | F9: ='Summary Sources-Uses'!E9 -> 0 | AV9: =SUM(H9:AU9) -> 0 | AW9: =F9-AV9 -> 0
B10: 3rd Mortgage (FEMA) | D10: =F10/F$16 -> 0.73088936 | F10: ='Summary Sources-Uses'!E10 -> 0 | H10: =1714964.59 -> 1714964.6 | J10: =J103-J13 -> 578426.56 | K10: =K103-K13 -> 875422.41 | L10: =L103-L13 -> 957754.35 | M10: =(H7+I7+H11)-(J10+K10+L10) -> 672376.55 | O10: =M7 -> 300377.8 | P10: =P103-P13 -> 967673.07 | Q10: =(N7+O7)-(O10+P10) -> 234973.43 | S10: =S103-S13 -> 967184.93 | T10: =(Q7+R7)-(S10) -> 762245.12 | V10: =T7 -> 209939.81 | W10: =W103-W13 -> 892845.72 | X10: =(F9+F10)-SUM(H10:W10) -> 17865816 | AV10: =SUM(H10:AU10) -> 27000000 | AW10: =F10-AV10 -> -3000000
B11: L.P. Capital Contribution | D11: =F11/F$16 -> 0.25066236 | F11: ='Credit Delivery & Pay-Ins'!N7 -> 8230926.5 | H11: ='Credit Delivery & Pay-Ins'!N22 -> 823092.65 | AE11: =('Credit Delivery & Pay-Ins'!N44)-(SUM(AF11:AN11)) -> 3768179.4 | AF11: =AF103-AF13 -> 105722.27 | AG11: =AG103-AG13 -> 105722.27 | AH11: =AH103-AH13 -> 105722.27 | AI11: =AI103-AI13 -> 105722.27 | AJ11: =AJ103-AJ13 -> 65722.271 | AK11: =AK103-AK13 -> 47388.938 | AL11: =AL103-AL13 -> 47388.938 | AM11: =AM103-AM13 -> 47388.938 | AN11: =AN103-AN13 -> 47388.938 | AP11: 0 | AQ11: 0 | AR11: ='Credit Delivery & Pay-Ins'!N58 -> 2961487.4 | AV11: =SUM(H11:AU11) -> 8230926.5 | AW11: =F11-AV11 -> 0
B12: GAP | D12: =F12/F$16 -> 0 | F12: ='Summary Sources-Uses'!E12 -> 0 | AV12: =SUM(H12:AU12) -> 0 | AW12: =F12-AV12 -> 0
B13: Bond Arbitrage Earnings | D13: =F13/F$16 -> 0.036139361 | F13: ='Summary Sources-Uses'!E18 -> 1186697.6 | H13: =H115 -> 0 | I13: =I115 -> 33905.646 | J13: =J115 -> 33905.646 | K13: =K115 -> 33905.646 | L13: =L115 -> 33905.646 | M13: =M115 -> 33905.646 | N13: =N115 -> 33905.646 | O13: =O115 -> 33905.646 | ... AQ13: =AQ115 -> 33905.646 | AV13: =SUM(H13:AU13) -> 1186697.6 | AW13: =F13-AV13 -> 0
B14: 45L Credits | D14: =F14/F$16 -> 0 | F14: ='Summary Sources-Uses'!E13 -> 0 | AV14: =SUM(H14:AU14) -> 0 | AW14: =F14-AV14 -> 0
B15: Deferred Developer Fee | D15: =F15/F$16 -> -0.57347153 | F15: ='Summary Sources-Uses'!E17 -> -18830917 | AV15: =SUM(H15:AU15) -> 0 | AW15: =F15-AV15 -> -18830917
C16: Total Sources: | F16: =SUM(F8:F15) -> 32836707 | G16: =SUM(G7:G15) -> 0 | H16: =SUM(H7:H15) -> 4902611.6 | I16: =SUM(I7:I15) -> -69761.515 | J16: =SUM(J7:J15) -> 612332.21 | K16: =SUM(K7:K15) -> 909328.05 | L16: =SUM(L7:L15) -> 991660 | M16: =SUM(M7:M15) -> 1006660 | N16: =SUM(N7:N15) -> 868312.08 | ... AR16: =SUM(AR7:AR15) -> 9452366.7 | AT16: =SUM(AT7:AT15) -> 0 | AU16: =SUM(AU7:AU15) -> 0 | AV16: =SUM(H16:AU16) -> 51667624 | AW16: =F16-AV16 -> -18830917
E17: % of Equity Capital | G17: =G11/$F11 -> 0 | H17: =H11/$F11 -> 0.1 | I17: =I11/$F11 -> 0 | J17: =J11/$F11 -> 0 | K17: =K11/$F11 -> 0 | L17: =L11/$F11 -> 0 | M17: =M11/$F11 -> 0 | N17: =N11/$F11 -> 0 | ... AR17: =AR11/$F11 -> 0.3598 | AT17: =AT11/$F11 -> 0 | AU17: =AU11/$F11 -> 0 | AV17: =SUM(H17:AR17) -> 1
A19: USES | F19: =H103-H11 -> 4079519 | H19: =H3 -> 46447 | I19: =I3 -> 46478 | J19: =J3 -> 46508 | K19: =K3 -> 46539 | L19: =L3 -> 46569 | M19: =M3 -> 46600 | N19: =N3 -> 46631 | O19: =O3 -> 46661 | ... AR19: =AR3 -> 47543 | AT19: =AT3 -> 47604 | AU19: =AU3 -> 47635
A20: Acquisition Costs | E20: per unit
B21: ='Development Budget'!C9 -> Land/Ground Lease Prepayment | E21: =F21/'Rent Schedule'!$D$26 -> 0 | F21: ='Development Budget'!G9 -> 0 | H21: =F21 -> 0 | AV21: =SUM(H21:AQ21) -> 0 | AW21: =F21-AV21 -> 0
E22: =F22/[6]Rent_Schedule!$E$25 -> 0
