Workbook
Name AddRevY1: 'Rent Schedule'!$K$34
Name CommRent: Inputs!$E$58
Name CommSqFt: Inputs!$C$58
Name ExpInfl: Inputs!$C$36
Name ExpTotalY1: 'Operating Expense'!$E$20
Name GrossOpEx: 'Operating Expense'!$E$20
Name GrossRentIncomeY1: 'Rent Schedule'!$K$26
Name LIUnits: 'Rent Schedule'!$D$26
Name NetIncomeY1: 'Rent Schedule'!$K$42
Name NOI: '20yr Proforma'!$F$24
Name ProjName: 'Constr Sources-Uses'!$A$2
Name ProjName: 'Perm Sources-Uses'!$A$2
Name ProjName: "'Summary_Sources-Uses'!$A$2"
Name PropTaxes: 'Operating Expense'!$E$133
Name ReplRes: 'Operating Expense'!$E$21
Name ReplReserve: Inputs!$C$37
Name RevInfl: Inputs!$C$35
Name Tenancy: 1-Inputs!$C$34
Name TotalUnitCount: Inputs!$C$2
Name TtlUnits: 'Rent Schedule'!$D$26
Name Vacancy: Inputs!$C$34
Name VacRate: Inputs!$C$34

Sheet READ ME — TEMPLATE
A1: I | B1: REO, LLC — LIHTC UNDERWRITING MODEL TEMPLATE
B2: Based on Columbia at Independence Heights II Structure
B4: HOW TO USE THIS TEMPLATE
B5: 1. Save a copy of this file with your new project name before editing.
B6: 2. Start on the INPUTS sheet — fill in all blue-highlighted cells with your deal assumptions.
B7: 3. Move to RENT SCHEDULE — enter your unit mix, set-asides, and projected rents.
B8: 4. Complete DEVELOPMENT BUDGET — enter all line-item costs and basis eligibility.
B9: 5. Complete OPERATING EXPENSE — enter your projected operating budget.
B10: 6. Update SUMMARY SOURCES-USES — enter debt terms, equity pricing, source names.
B11: 7. Complete CREDIT DELIVERY & PAY-INS — enter lease-up schedule and equity pay-in timing.
B12: 8. Complete FLOW OF FUNDS — enter monthly construction draw percentages.
B13: 9. Update DEVELOPER FEE SCHEDULE — enter partner entities and split percentages.
B14: 10. Review 20YR PROFORMA and 25% TEST — these are formula-driven and auto-calculate.
... B45: LHC (Louisiana) applications with minor modifications to scoring/compliance sheets

Sheet Inputs
B1: Project | C1: Live Oak Manor Residences — Phase 1 | E1: [Version] | L1: apex apartments with ext detention
B2: Number of Units | C2: 61
K3: 231250 | L3: buildable NRSF per JHP
B4: Acres | K4: 1200 | L4: avg unit SF
B5: Units/Acre | C5: 4.88 | K5: 192.70833
B6: Acquisition Price | E6: per unit
B8: Type of Allocation
B10: Max Credit Allocation | F10: GA: $950,000; TX: $1,500,000
B11: Max Dev. Fee Allowable | F11: GA: $1.8MM for 9%, $2.5MM for 4%
B13: Rents
C14: 2025 FY MTSP LIHTC rents | G14: 2023 FMR+10%
C15: 30% LIHTC | D15: 50% LIHTC | E15: 60% LIHTC | F15: 30% PBV | G15: 50% PBV | H15: 80% LIHTC | J15: Market | K15: FMR | L15: UA | N15: SF | O15: Mix | P15: Market Rate/SF
B16: 1 BR | L16: 130 | P16: 0
B17: 2 BR | L17: 173 | P17: 0
B18: 3 BR | L18: 214 | P18: 0
B19: 4 BR | O19: 0
B20: UA's | C20: Y | D20: Y | E20: Y | F20: Y | G20: Y | H20: y | I20: Y | J20: N
L21: *asssume $20/unit savings
B22: Set Asides | C22: Income Limits | D22: Total Mix | F22: Of | G22: Less
B23: 30% PBV | F23: of Total | H23: 0
B24: 50% PBV | F24: of Total | H24: 0 | L24: Tax Abatement
B25: 60% LIHTC | F25: Plug | T25: 1.592
B26: 80% LIHTC | F26: of Total | H26: 0 | L26: 2
F27: of Total | H27: 0 | L27: 3
F28: of Total | G28: 0 | H28: 0 | L28: 4
F29: of Total | G29: 0 | H29: 0 | L29: 5
F30: of Total | G30: 0 | H30: 0 | L30: 6
F31: of Total | G31: 0 | H31: 0 | L31: 7
B32: Market | C32: None | L32: 8
D33: 61 | E33: 0.5852459 | F33: income avg | L33: 9
B34: Vacancy Rate | L34: 10
B35: Revenue Inflation | L35: 11 | O35: 1115.4
B36: Expense Inflation | L36: 12 | O36: 1328.8
B37: Replacement Reserve | D37: per units | L37: 13 | O37: 1763.3
L38: 14
L39: 15
B40: Start Year | L40: 16
A41: Month | D41: Equity Schedule | E41: Fee Schedule | L41: 17
B42: Start | L42: 18
B43: Application | L43: 19
...

Sheet Constr Sources-Uses
A1: CONSTRUCTION SOURCES & USES
A2: [Project Name]
A3: [Project Description] | L3: =G5&" Family Units" -> Family Units
L4: [Affordability Mix]
A5: SOURCES & USES - Construction Period | H5: units
B7: Sources: | F7: Per Unit | H7: Uses: | K7: Total | L7: Per Unit
B8: First Mortgage | D8: Tax-Exempt Bonds (25% Test) | E8: ='25% Test'!F5 -> 0 | F8: =E8/G$5 -> #DIV/0! | G8: =E8/$E$23 -> #DIV/0! | H8: Acquisition Costs | K8: ='Development Budget'!H10 -> 0 | L8: =K8/G$5 -> #DIV/0! | M8: =K8/$K$23 -> #DIV/0!
B9: 2nd Mortgage | D9: Gap Funding (TBD Source) | E9: =K23-SUM(E8,E10:E18) -> 0 | F9: =E9/G$5 -> #DIV/0! | G9: =E9/$E$23 -> #DIV/0! | H9: Construction Costs | K9: ='Development Budget'!H21 -> 0 | L9: =K9/G$5 -> #DIV/0! | M9: =K9/$K$23 -> #DIV/0! | P9: CHANGES to SOURCES
B10: 3rd Mortgage | D10: LHC Soft Loan / Capital Magnet / FHLB AHP | F10: =E10/G$5 -> #DIV/0! | G10: =E10/$E$23 -> #DIV/0! | H10: Predevelopment Costs | K10: ='Development Budget'!H29 -> 0 | L10: =K10/G$5 -> #DIV/0! | M10: =K10/$K$23 -> #DIV/0!
B11: 4th Mortgage | D11: =E56 -> 0 | F11: =E11/G$5 -> #DIV/0! | G11: =E11/$E$23 -> #DIV/0! | H11: Financing | K11: ='Development Budget'!H40 -> 0 | L11: =K11/G$5 -> #DIV/0! | M11: =K11/$K$23 -> #DIV/0! | P11: 1 | S11: QCT Credits
B12: Funding Gap (Unfunded) | D12: n.a. | F12: =E12/G$5 -> #DIV/0! | G12: =E12/$E$23 -> #DIV/0! | H12: Professional Services | K12: ='Development Budget'!H54 -> 0 | L12: =K12/G$5 -> #DIV/0! | M12: =K12/$K$23 -> #DIV/0! | R12: =E37*10 -> 0 | S12: noQCT
B13: Other Equity | D13: Developer Cash Equity | F13: =E13/G$5 -> #DIV/0! | G13: =E13/$E$23 -> #DIV/0! | H13: Local Government Fees | K13: ='Development Budget'!H60 -> 0 | L13: =K13/G$5 -> #DIV/0! | M13: =K13/$K$23 -> #DIV/0! | R13: =R12-R11 -> 0 | S13: Loss in credits
B14: Other grant/loan | D14: FHLB of Dallas AHP (included in 3rd Mortgage) | F14: =E14/G$5 -> #DIV/0! | G14: =E14/$E$23 -> #DIV/0! | H14: Permanent Financing Fees | K14: ='Development Budget'!H67 -> 0 | L14: =K14/G$5 -> #DIV/0! | M14: =K14/$K$23 -> #DIV/0!
B15: LIHTC Equity (4%)-Fed | D15: TBD — Tax Credit Investor | E15: =E39 -> 0 | F15: =E15/G$5 -> #DIV/0! | G15: =E15/$E$23 -> #DIV/0! | H15: Tax Credit Costs | K15: ='Development Budget'!H75 -> 0 | L15: =K15/G$5 -> #DIV/0! | M15: =K15/$K$23 -> #DIV/0! | S15: QCT Equity
B16: LIHTC Equity (4%)-State | D16: [State Investor] | E16: =E41 -> 0 | F16: =E16/G$5 -> #DIV/0! | G16: =E16/$E$23 -> #DIV/0! | H16: Equity Costs | K16: ='Development Budget'!H81 -> 0 | L16: =K16/G$5 -> #DIV/0! | M16: =K16/$K$23 -> #DIV/0! | R16: =E15 -> 0 | S16: noQCT
B17: Deferred Devel Fee | D17: developer | E17: =K20 -> 0 | F17: =E17/G$5 -> #DIV/0! | G17: =E17/$E$23 -> #DIV/0! | H17: Start Up and Reserves | K17: ='Development Budget'!H88 -> 0 | L17: =K17/G$5 -> #DIV/0! | M17: =K17/$K$23 -> #DIV/0! | R17: =R16-R15 -> 0 | S17: Loss in Equity
B18: Earnings on GIC (set equal to interest exp) | G18: =E18/$E$23 -> #DIV/0! | H18: Other Costs | K18: ='Development Budget'!H91 -> 0 | L18: =K18/G$5 -> #DIV/0! | M18: =K18/$K$23 -> #DIV/0!
C20: percent of fee deferred | D20: =E17/K20 -> #DIV/0! | H20: Developer Fee | L20: =K20/G$5 -> #DIV/0! | M20: =K20/$K$23 -> #DIV/0!
C21: Payback period | D21: ='20yr Proforma'!C54 -> #REF!
R22: Permanent Debt
B23: Total Sources: | E23: =SUM(E8:E18) -> 0 | F23: =E23/G$5 -> #DIV/0! | H23: Total Uses: | K23: =SUM(K8:K18)+K20 -> 0 | L23: =K23/G$5 -> #DIV/0! | S23: QCT Perm Debt
R24: =E8+K51 -> 0 | S24: noQCT
B25: Funding Gap (Sources - Uses): | E25: =E23-K23 -> 0 | F25: =E25/G$5 -> #DIV/0! | Q25: =R25/R23 -> #DIV/0! | R25: =R24-R23 -> 0 | S25: Increase in debt
R27: Deferred Developer Fee
B28: LIHTC Equity | S28: QCT DDF
B29: Total Eligible Costs | E29: ='Development Budget'!J94 -> 0 | R29: =E17 -> 0 | S29: noQCT
B30: Percentage Low Income | D30: 1 | Q30: =R30/R28 -> #DIV/0! | R30: =R29-R28 -> 0 | S30: Increase in DDF
B31: Eligible Basis Acquis. | D31: 1
B32: Eligible Basis-Dev. Cost | D32: ='Rent Schedule'!D27 -> 1 | E32: =E29*D32 -> 0 | R32: FEMA Allocation
B33: Combined Basis | E33: =E31+E32 -> 0 | R33: 0 | S33: QCT FEMA
B34: Boost | D34: 1 | R34: =E10 -> 0 | S34: noQCT
B35: Qualified Basis: | E35: =E33*D34 -> 0 | Q35: =R35/R33 -> #DIV/0! | R35: =R34-R33 -> 0 | S35: Increase in FEMA
B36: Eligible Annual Credit: | D36: 0.04 | E36: =E35*D36 -> 0
B37: LIHTC allocation | E37: =E36 -> 0
B38: Federal Equity Pricing ($/credit) | E38: =E37*10*D38 -> 0
B39: Total Federal LIHTC Equity | E39: =E38*0.9999 -> 0 | F39: 99.99% to LP investor
B40: State Equity Pricing ($/credit) | E40: =E37*10*D40 -> 0
B41: Total State LIHTC Equity | E41: =E40*0.9999 -> 0
B43: Total Equity Yield | E43: =E39+E41 -> 0
B45: 45L Credits | D45: =D38 -> 0
...

Sheet Perm Sources-Uses
A1: PERMANENT SOURCES & USES
A2: [Project Name]
A3: [Project Description] | L3: =G5&" Family Units" -> Family Units
L4: [Affordability Mix]
A5: SOURCES & USES - Permanent Financing | H5: units
B7: Sources: | F7: Per Unit | H7: Uses: | K7: Total | L7: Per Unit
B8: First Mortgage | D8: Tax-Exempt Bonds (25% Test) | E8: ='25% Test'!F5 -> 0 | F8: =E8/G$5 -> #DIV/0! | G8: =E8/$E$23 -> #DIV/0! | H8: Acquisition Costs | K8: ='Development Budget'!H10 -> 0 | L8: =K8/G$5 -> #DIV/0! | M8: =K8/$K$23 -> #DIV/0!
B9: 2nd Mortgage | D9: Gap Funding (TBD Source) | E9: =K23-SUM(E8,E10:E18) -> 0 | F9: =E9/G$5 -> #DIV/0! | G9: =E9/$E$23 -> #DIV/0! | H9: Construction Costs | K9: ='Development Budget'!H21 -> 0 | L9: =K9/G$5 -> #DIV/0! | M9: =K9/$K$23 -> #DIV/0! | P9: CHANGES to SOURCES
B10: 3rd Mortgage | D10: LHC Soft Loan / Capital Magnet / FHLB AHP | F10: =E10/G$5 -> #DIV/0! | G10: =E10/$E$23 -> #DIV/0! | H10: Predevelopment Costs | K10: ='Development Budget'!H29 -> 0 | L10: =K10/G$5 -> #DIV/0! | M10: =K10/$K$23 -> #DIV/0!
B11: 4th Mortgage | D11: =E56 -> 0 | F11: =E11/G$5 -> #DIV/0! | G11: =E11/$E$23 -> #DIV/0! | H11: Financing | K11: ='Development Budget'!H40 -> 0 | L11: =K11/G$5 -> #DIV/0! | M11: =K11/$K$23 -> #DIV/0! | P11: 1 | S11: QCT Credits
B12: Funding Gap (Unfunded) | D12: n.a. | F12: =E12/G$5 -> #DIV/0! | G12: =E12/$E$23 -> #DIV/0! | H12: Professional Services | K12: ='Development Budget'!H54 -> 0 | L12: =K12/G$5 -> #DIV/0! | M12: =K12/$K$23 -> #DIV/0! | R12: =E37*10 -> 0 | S12: noQCT
B13: Other Equity | D13: Developer Cash Equity | F13: =E13/G$5 -> #DIV/0! | G13: =E13/$E$23 -> #DIV/0! | H13: Local Government Fees | K13: ='Development Budget'!H60 -> 0 | L13: =K13/G$5 -> #DIV/0! | M13: =K13/$K$23 -> #DIV/0! | R13: =R12-R11 -> 0 | S13: Loss in credits
B14: Other grant/loan | D14: FHLB of Dallas AHP (included in 3rd Mortgage) | F14: =E14/G$5 -> #DIV/0! | G14: =E14/$E$23 -> #DIV/0! | H14: Permanent Financing Fees | K14: ='Development Budget'!H67 -> 0 | L14: =K14/G$5 -> #DIV/0! | M14: =K14/$K$23 -> #DIV/0!
B15: LIHTC Equity (4%)-Fed | D15: TBD — Tax Credit Investor | E15: =E39 -> 0 | F15: =E15/G$5 -> #DIV/0! | G15: =E15/$E$23 -> #DIV/0! | H15: Tax Credit Costs | K15: ='Development Budget'!H75 -> 0 | L15: =K15/G$5 -> #DIV/0! | M15: =K15/$K$23 -> #DIV/0! | S15: QCT Equity
B16: LIHTC Equity (4%)-State | D16: [State Investor] | E16: =E41 -> 0 | F16: =E16/G$5 -> #DIV/0! | G16: =E16/$E$23 -> #DIV/0! | H16: Equity Costs | K16: ='Development Budget'!H81 -> 0 | L16: =K16/G$5 -> #DIV/0! | M16: =K16/$K$23 -> #DIV/0! | R16: =E15 -> 0 | S16: noQCT
B17: Deferred Devel Fee | D17: developer | E17: =K20 -> 0 | F17: =E17/G$5 -> #DIV/0! | G17: =E17/$E$23 -> #DIV/0! | H17: Start Up and Reserves | K17: ='Development Budget'!H88 -> 0 | L17: =K17/G$5 -> #DIV/0! | M17: =K17/$K$23 -> #DIV/0! | R17: =R16-R15 -> 0 | S17: Loss in Equity
B18: Earnings on GIC (set equal to interest exp) | G18: =E18/$E$23 -> #DIV/0! | H18: Other Costs | K18: ='Development Budget'!H91 -> 0 | L18: =K18/G$5 -> #DIV/0! | M18: =K18/$K$23 -> #DIV/0!
C20: percent of fee deferred | D20: =E17/K20 -> #DIV/0! | H20: Developer Fee | L20: =K20/G$5 -> #DIV/0! | M20: =K20/$K$23 -> #DIV/0!
C21: Payback period | D21: ='20yr Proforma'!C54 -> #REF!
R22: Permanent Debt
B23: Total Sources: | E23: =SUM(E8:E18) -> 0 | F23: =E23/G$5 -> #DIV/0! | H23: Total Uses: | K23: =SUM(K8:K18)+K20 -> 0 | L23: =K23/G$5 -> #DIV/0! | S23: QCT Perm Debt
R24: =E8+K51 -> 0 | S24: noQCT
B25: Funding Gap (Sources - Uses): | E25: =E23-K23 -> 0 | F25: =E25/G$5 -> #DIV/0! | Q25: =R25/R23 -> #DIV/0! | R25: =R24-R23 -> 0 | S25: Increase in debt
R27: Deferred Developer Fee
B28: LIHTC Equity | S28: QCT DDF
B29: Total Eligible Costs | E29: ='Development Budget'!J94 -> 0 | R29: =E17 -> 0 | S29: noQCT
B30: Percentage Low Income | D30: 1 | Q30: =R30/R28 -> #DIV/0! | R30: =R29-R28 -> 0 | S30: Increase in DDF
B31: Eligible Basis Acquis. | D31: 1
B32: Eligible Basis-Dev. Cost | D32: ='Rent Schedule'!D27 -> 1 | E32: =E29*D32 -> 0 | R32: FEMA Allocation
B33: Combined Basis | E33: =E31+E32 -> 0 | R33: =20000000 -> 20000000 | S33: QCT FEMA
B34: Boost | D34: 1 | R34: =E10 -> 0 | S34: noQCT
B35: Qualified Basis: | E35: =E33*D34 -> 0 | Q35: =R35/R33 -> -1 | R35: =R34-R33 -> -20000000 | S35: Increase in FEMA
B36: Eligible Annual Credit: | D36: 0.04 | E36: =E35*D36 -> 0
B37: LIHTC allocation | E37: =E36 -> 0
B38: Federal Equity Pricing ($/credit) | E38: =E37*10*D38 -> 0
B39: Total Federal LIHTC Equity | E39: =E38*0.9999 -> 0 | F39: 99.99% to LP investor
B40: State Equity Pricing ($/credit) | E40: =E37*10*D40 -> 0
B41: Total State LIHTC Equity | E41: =E40*0.9999 -> 0
B43: Total Equity Yield | E43: =E39+E41 -> 0
B45: 45L Credits | D45: =D38 -> 0
...

Sheet Amortization Table
A1: AMORTIZATION TABLE — DEBT CAPACITY ANALYSIS
A2: ='[1]Summary_Sources-Uses'!A2 -> #REF!
A3: Project Type
A5: LOAN ASSUMPTIONS
A6: Loan Amount (1st Mortgage) | C6: ='Perm Sources-Uses'!K49 -> 0
A7: Interest Rate | C7: ='Perm Sources-Uses'!H49 -> 0
A8: Amortization (years) | C8: ='Perm Sources-Uses'!I49 -> 0
A9: Loan Term (years) | C9: ='Perm Sources-Uses'!J49 -> 0
A10: Monthly Payment | C10: =IF(C6=0,0,-PMT(C7/12,C8*12,C6)) -> 0
A11: Annual Debt Service | C11: =C10*12 -> 0
A13: DEBT CAPACITY ANALYSIS
A14: Year 1 NOI | C14: ='20yr Proforma'!F24 -> #VALUE!
A15: Required DSCR (underwriting) | C15: 1.2
A16: Max Annual Debt Service at DSCR | C16: =IF(C15=0,0,C14/C15) -> #VALUE!
A17: Max Supportable Debt | C17: =IF(C7=0,0,-PV(C7/12,C8*12,C16/12)) -> 0
A19: AMORTIZATION SCHEDULE
A20: Year | B20: Beg. Balance | C20: Annual Payment | D20: Interest | E20: Principal | F20: End. Balance | G20: NOI | H20: DSCR
A21: 1 | B21: =C6 -> 0 | C21: =IF($C$6=0,0,$C$11) -> 0 | D21: =B21*$C$7 -> 0 | E21: =C21-D21 -> 0 | F21: =B21-E21 -> 0 | G21: ='20yr Proforma'!F24 -> #VALUE! | H21: =IF(C21=0,0,G21/C21) -> 0
A22: 2 | B22: =F21 -> 0 | C22: =IF($C$6=0,0,$C$11) -> 0 | D22: =B22*$C$7 -> 0 | E22: =C22-D22 -> 0 | F22: =B22-E22 -> 0 | G22: ='20yr Proforma'!G24 -> #VALUE! | H22: =IF(C22=0,0,G22/C22) -> 0
A23: 3 | B23: =F22 -> 0 | C23: =IF($C$6=0,0,$C$11) -> 0 | D23: =B23*$C$7 -> 0 | E23: =C23-D23 -> 0 | F23: =B23-E23 -> 0 | G23: ='20yr Proforma'!H24 -> #VALUE! | H23: =IF(C23=0,0,G23/C23) -> 0
A24: 4 | B24: =F23 -> 0 | C24: =IF($C$6=0,0,$C$11) -> 0 | D24: =B24*$C$7 -> 0 | E24: =C24-D24 -> 0 | F24: =B24-E24 -> 0 | G24: ='20yr Proforma'!I24 -> #VALUE! | H24: =IF(C24=0,0,G24/C24) -> 0
A25: 5 | B25: =F24 -> 0 | C25: =IF($C$6=0,0,$C$11) -> 0 | D25: =B25*$C$7 -> 0 | E25: =C25-D25 -> 0 | F25: =B25-E25 -> 0 | G25: ='20yr Proforma'!J24 -> #VALUE! | H25: =IF(C25=0,0,G25/C25) -> 0
A26: 6 | B26: =F25 -> 0 | C26: =IF($C$6=0,0,$C$11) -> 0 | D26: =B26*$C$7 -> 0 | E26: =C26-D26 -> 0 | F26: =B26-E26 -> 0 | G26: ='20yr Proforma'!K24 -> #VALUE! | H26: =IF(C26=0,0,G26/C26) -> 0
A27: 7 | B27: =F26 -> 0 | C27: =IF($C$6=0,0,$C$11) -> 0 | D27: =B27*$C$7 -> 0 | E27: =C27-D27 -> 0 | F27: =B27-E27 -> 0 | G27: ='20yr Proforma'!L24 -> #VALUE! | H27: =IF(C27=0,0,G27/C27) -> 0
A28: 8 | B28: =F27 -> 0 | C28: =IF($C$6=0,0,$C$11) -> 0 | D28: =B28*$C$7 -> 0 | E28: =C28-D28 -> 0 | F28: =B28-E28 -> 0 | G28: ='20yr Proforma'!M24 -> #VALUE! | H28: =IF(C28=0,0,G28/C28) -> 0
A29: 9 | B29: =F28 -> 0 | C29: =IF($C$6=0,0,$C$11) -> 0 | D29: =B29*$C$7 -> 0 | E29: =C29-D29 -> 0 | F29: =B29-E29 -> 0 | G29: ='20yr Proforma'!N24 -> #VALUE! | H29: =IF(C29=0,0,G29/C29) -> 0
A30: 10 | B30: =F29 -> 0 | C30: =IF($C$6=0,0,$C$11) -> 0 | D30: =B30*$C$7 -> 0 | E30: =C30-D30 -> 0 | F30: =B30-E30 -> 0 | G30: ='20yr Proforma'!O24 -> #VALUE! | H30: =IF(C30=0,0,G30/C30) -> 0
A31: 11 | B31: =F30 -> 0 | C31: =IF($C$6=0,0,$C$11) -> 0 | D31: =B31*$C$7 -> 0 | E31: =C31-D31 -> 0 | F31: =B31-E31 -> 0 | G31: ='20yr Proforma'!P24 -> #VALUE! | H31: =IF(C31=0,0,G31/C31) -> 0
A32: 12 | B32: =F31 -> 0 | C32: =IF($C$6=0,0,$C$11) -> 0 | D32: =B32*$C$7 -> 0 | E32: =C32-D32 -> 0 | F32: =B32-E32 -> 0 | G32: ='20yr Proforma'!Q24 -> #VALUE! | H32: =IF(C32=0,0,G32/C32) -> 0
A33: 13 | B33: =F32 -> 0 | C33: =IF($C$6=0,0,$C$11) -> 0 | D33: =B33*$C$7 -> 0 | E33: =C33-D33 -> 0 | F33: =B33-E33 -> 0 | G33: ='20yr Proforma'!R24 -> #VALUE! | H33: =IF(C33=0,0,G33/C33) -> 0
A34: 14 | B34: =F33 -> 0 | C34: =IF($C$6=0,0,$C$11) -> 0 | D34: =B34*$C$7 -> 0 | E34: =C34-D34 -> 0 | F34: =B34-E34 -> 0 | G34: ='20yr Proforma'!S24 -> #VALUE! | H34: =IF(C34=0,0,G34/C34) -> 0
A35: 15 | B35: =F34 -> 0 | C35: =IF($C$6=0,0,$C$11) -> 0 | D35: =B35*$C$7 -> 0 | E35: =C35-D35 -> 0 | F35: =B35-E35 -> 0 | G35: ='20yr Proforma'!T24 -> #VALUE! | H35: =IF(C35=0,0,G35/C35) -> 0
A36: 16 | B36: =F35 -> 0 | C36: =IF($C$6=0,0,$C$11) -> 0 | D36: =B36*$C$7 -> 0 | E36: =C36-D36 -> 0 | F36: =B36-E36 -> 0 | G36: ='20yr Proforma'!U24 -> #VALUE! | H36: =IF(C36=0,0,G36/C36) -> 0
A37: 17 | B37: =F36 -> 0 | C37: =IF($C$6=0,0,$C$11) -> 0 | D37: =B37*$C$7 -> 0 | E37: =C37-D37 -> 0 | F37: =B37-E37 -> 0 | G37: ='20yr Proforma'!V24 -> #VALUE! | H37: =IF(C37=0,0,G37/C37) -> 0
A38: 18 | B38: =F37 -> 0 | C38: =IF($C$6=0,0,$C$11) -> 0 | D38: =B38*$C$7 -> 0 | E38: =C38-D38 -> 0 | F38: =B38-E38 -> 0 | G38: ='20yr Proforma'!W24 -> #VALUE! | H38: =IF(C38=0,0,G38/C38) -> 0
A40: TOTALS | C40: =SUM(C21:C38) -> 0 | D40: =SUM(D21:D38) -> 0 | E40: =SUM(E21:E38) -> 0
A42: ="Balloon Balance at Maturity (Year "&C9&")" -> Balloon Balance at Maturity (Year 0) | C42: =F38 -> 0
A44: Cumulative Interest Paid | C44: =D40 -> 0
A45: Cumulative Principal Paid | C45: =E40 -> 0
A46: Interest as % of Total Payments | C46: =IF(C40=0,0,C44/C40) -> 0

Sheet DDF Note
A1: DEFERRED DEVELOPER FEE NOTE
A2: [Project Name]
A3: Project Type
A5: NOTE TERMS
A6: Total Developer Fee | C6: ='Developer Fee Schedule'!A9 -> 0
A7: Developer Fee Paid at Milestones (Max Fee) | C7: ='Developer Fee Schedule'!K9 -> 0
A8: Deferred Developer Fee (DDF) | C8: ='Perm Sources-Uses'!K20 -> 0
A9: % of Total Fee Deferred | C9: =C8/C6 -> #DIV/0!
A10: Interest Rate on DDF Note | C10: ='20yr Proforma'!D64 -> 0
A11: Payback Period (years) | C11: ='20yr Proforma'!E33 -> 12
A12: Payment Source | C12: Available Cash Flow after Debt Service & LP A/M Fee
A14: DEFERRED DEVELOPER FEE SCHEDULE
A15: Year | B15: Beg. DDF Balance | C15: Interest Accrued | D15: Cash Flow after DS | E15: LP A/M Fee | F15: Available for DDF | G15: DDF Payment | H15: End. DDF Balance | I15: Cumul. Paid
A16: 1 | B16: =$C$8 -> 0 | C16: =B16*$C$10 -> 0 | D16: ='20yr Proforma'!F39 -> #VALUE! | E16: =-'20yr Proforma'!F41 -> 8500 | F16: =MAX(D16-E16,0) -> #VALUE! | G16: =MIN(F16,B16+C16) -> #VALUE! | H16: =B16+C16-G16 -> #VALUE! | I16: =G16 -> #VALUE!
A17: 2 | B17: =H16 -> #VALUE! | C17: =B17*$C$10 -> #VALUE! | D17: ='20yr Proforma'!G39 -> #VALUE! | E17: =-'20yr Proforma'!G41 -> #VALUE! | F17: =MAX(D17-E17,0) -> #VALUE! | G17: =MIN(F17,B17+C17) -> #VALUE! | H17: =B17+C17-G17 -> #VALUE! | I17: =I16+G17 -> #VALUE!
A18: 3 | B18: =H17 -> #VALUE! | C18: =B18*$C$10 -> #VALUE! | D18: ='20yr Proforma'!H39 -> #VALUE! | E18: =-'20yr Proforma'!H41 -> #VALUE! | F18: =MAX(D18-E18,0) -> #VALUE! | G18: =MIN(F18,B18+C18) -> #VALUE! | H18: =B18+C18-G18 -> #VALUE! | I18: =I17+G18 -> #VALUE!
A19: 4 | B19: =H18 -> #VALUE! | C19: =B19*$C$10 -> #VALUE! | D19: ='20yr Proforma'!I39 -> #VALUE! | E19: =-'20yr Proforma'!I41 -> #VALUE! | F19: =MAX(D19-E19,0) -> #VALUE! | G19: =MIN(F19,B19+C19) -> #VALUE! | H19: =B19+C19-G19 -> #VALUE! | I19: =I18+G19 -> #VALUE!
A20: 5 | B20: =H19 -> #VALUE! | C20: =B20*$C$10 -> #VALUE! | D20: ='20yr Proforma'!J39 -> #VALUE! | E20: =-'20yr Proforma'!J41 -> #VALUE! | F20: =MAX(D20-E20,0) -> #VALUE! | G20: =MIN(F20,B20+C20) -> #VALUE! | H20: =B20+C20-G20 -> #VALUE! | I20: =I19+G20 -> #VALUE!
A21: 6 | B21: =H20 -> #VALUE! | C21: =B21*$C$10 -> #VALUE! | D21: ='20yr Proforma'!K39 -> #VALUE! | E21: =-'20yr Proforma'!K41 -> #VALUE! | F21: =MAX(D21-E21,0) -> #VALUE! | G21: =MIN(F21,B21+C21) -> #VALUE! | H21: =B21+C21-G21 -> #VALUE! | I21: =I20+G21 -> #VALUE!
A22: 7 | B22: =H21 -> #VALUE! | C22: =B22*$C$10 -> #VALUE! | D22: ='20yr Proforma'!L39 -> #VALUE! | E22: =-'20yr Proforma'!L41 -> #VALUE! | F22: =MAX(D22-E22,0) -> #VALUE! | G22: =MIN(F22,B22+C22) -> #VALUE! | H22: =B22+C22-G22 -> #VALUE! | I22: =I21+G22 -> #VALUE!
A23: 8 | B23: =H22 -> #VALUE! | C23: =B23*$C$10 -> #VALUE! | D23: ='20yr Proforma'!M39 -> #VALUE! | E23: =-'20yr Proforma'!M41 -> #VALUE! | F23: =MAX(D23-E23,0) -> #VALUE! | G23: =MIN(F23,B23+C23) -> #VALUE! | H23: =B23+C23-G23 -> #VALUE! | I23: =I22+G23 -> #VALUE!
A24: 9 | B24: =H23 -> #VALUE! | C24: =B24*$C$10 -> #VALUE! | D24: ='20yr Proforma'!N39 -> #VALUE! | E24: =-'20yr Proforma'!N41 -> #VALUE! | F24: =MAX(D24-E24,0) -> #VALUE! | G24: =MIN(F24,B24+C24) -> #VALUE! | H24: =B24+C24-G24 -> #VALUE! | I24: =I23+G24 -> #VALUE!
A25: 10 | B25: =H24 -> #VALUE! | C25: =B25*$C$10 -> #VALUE! | D25: ='20yr Proforma'!O39 -> #VALUE! | E25: =-'20yr Proforma'!O41 -> #VALUE! | F25: =MAX(D25-E25,0) -> #VALUE! | G25: =MIN(F25,B25+C25) -> #VALUE! | H25: =B25+C25-G25 -> #VALUE! | I25: =I24+G25 -> #VALUE!
A26: 11 | B26: =H25 -> #VALUE! | C26: =B26*$C$10 -> #VALUE! | D26: ='20yr Proforma'!P39 -> #VALUE! | E26: =-'20yr Proforma'!P41 -> #VALUE! | F26: =MAX(D26-E26,0) -> #VALUE! | G26: =MIN(F26,B26+C26) -> #VALUE! | H26: =B26+C26-G26 -> #VALUE! | I26: =I25+G26 -> #VALUE!
A27: 12 | B27: =H26 -> #VALUE! | C27: =B27*$C$10 -> #VALUE! | D27: ='20yr Proforma'!Q39 -> #VALUE! | E27: =-'20yr Proforma'!Q41 -> #VALUE! | F27: =MAX(D27-E27,0) -> #VALUE! | G27: =MIN(F27,B27+C27) -> #VALUE! | H27: =B27+C27-G27 -> #VALUE! | I27: =I26+G27 -> #VALUE!
A28: 13 | B28: =H27 -> #VALUE! | C28: =B28*$C$10 -> #VALUE! | D28: ='20yr Proforma'!R39 -> #VALUE! | E28: =-'20yr Proforma'!R41 -> #VALUE! | F28: =MAX(D28-E28,0) -> #VALUE! | G28: =MIN(F28,B28+C28) -> #VALUE! | H28: =B28+C28-G28 -> #VALUE! | I28: =I27+G28 -> #VALUE!
A29: 14 | B29: =H28 -> #VALUE! | C29: =B29*$C$10 -> #VALUE! | D29: ='20yr Proforma'!S39 -> #VALUE! | E29: =-'20yr Proforma'!S41 -> #VALUE! | F29: =MAX(D29-E29,0) -> #VALUE! | G29: =MIN(F29,B29+C29) -> #VALUE! | H29: =B29+C29-G29 -> #VALUE! | I29: =I28+G29 -> #VALUE!
A30: 15 | B30: =H29 -> #VALUE! | C30: =B30*$C$10 -> #VALUE! | D30: ='20yr Proforma'!T39 -> #VALUE! | E30: =-'20yr Proforma'!T41 -> #VALUE! | F30: =MAX(D30-E30,0) -> #VALUE! | G30: =MIN(F30,B30+C30) -> #VALUE! | H30: =B30+C30-G30 -> #VALUE! | I30: =I29+G30 -> #VALUE!
A32: TOTALS | C32: =SUM(C16:C30) -> #VALUE! | G32: =SUM(G16:G30) -> #VALUE!
A34: SUMMARY
A35: Deferred Developer Fee (original) | C35: =C8 -> 0
A36: Total Interest Accrued | C36: =C32 -> #VALUE!
A37: Total DDF Repaid | C37: =G32 -> #VALUE!
A38: Remaining Unpaid Balance | C38: =C35+C36-C37 -> #VALUE!
A39: % of DDF Repaid within Payback Period | C39: =C37/(C35+C36) -> #VALUE!
A41: Year DDF Fully Repaid | C41: =IFERROR(MATCH(0,H16:H30,0),"Not within "&C11&" years") -> Not within 12 years

Sheet Development Budget
A2: Development Costs & Tax Treatment
A3: Live Oak Residences | G3: ='Rent Schedule'!D26 -> 0 | K3: 46111
B5: MATCHES LHC CORE APP (4%) | J5: Construction:
G6: Total | I6: Per Unit | J6: Section 42 | K6: Notes
J7: Basis Eligible
B8: Acquisition Costs
C9: Land/Ground Lease Prepayment | G9: =I9*$G$3 -> 0 | I9: 3798.3607 | J9: =G9 -> 0
G10: =G9 -> 0 | H10: =G10 -> 0 | J10: =J9 -> 0
B11: Construction Costs
C12: Hard Costs | G12: =I12*$G$3 -> 0 | I12: 233754.33 | J12: =G12 -> 0
C13: Sitework & Related Fees | G13: =I13*$G$3 -> 0 | I13: 44196.721 | J13: =G13 -> 0
C14: Structured Parking | G14: =I14*$G$3 -> 0 | J14: 0
C15: Utility Connection Fees | G15: =I15*$G$3 -> 0 | I15: 2708.1967 | J15: =G15 -> 0
C16: GC Overhead | G16: =I16*$G$3 -> 0 | J16: 0
C17: GC Profit | G17: =I17*$G$3 -> 0 | J17: 0
C18: Builders Risk Insurance | G18: =I18*$G$3 -> 0 | J18: 0
C19: Payment and Performance Bond | G19: =I19*$G$3 -> 0 | J19: 0
C20: Construction Contingency (5%) | G20: =I20*$G$3 -> 0 | I20: 13897.552 | J20: =G20 -> 0
G21: =SUM(G12:G20) -> 0 | H21: =G21 -> 0 | J21: =SUM(J12:J20) -> 0
B22: Predevelopment Costs
C23: Property Appraisal | G23: =I23*$G$3 -> 0 | J23: 0
C24: Market Study | G24: =I24*$G$3 -> 0 | I24: 573.77049 | J24: =G24 -> 0
C25: Environmental Report(s) | G25: =I25*$G$3 -> 0 | I25: 459.01639 | J25: =G25 -> 0
C26: Soil Borings | G26: =I26*$G$3 -> 0 | I26: 737.70492 | J26: =G26 -> 0
C27: Boundary and Topographical Survey | G27: =I27*$G$3 -> 0 | I27: 295.08197 | J27: =G27 -> 0
C28: Zoning/Site Plan Fees | G28: =I28*$G$3 -> 0 | J28: 0
G29: =SUM(G23:G28) -> 0 | H29: =G29 -> 0 | J29: =SUM(J23:J28) -> 0
B30: Financing
C31: Construction Financing and Placement Fees | G31: =I31*$G$3 -> 0 | J31: 0
C32: Construction Loan Interest | G32: =I32*$G$3 -> 0 | I32: 16461.213 | J32: =G32 -> 0
C33: Bond Interst (Fully Drawn) | G33: =I33*$G$3 -> 0 | J33: =G33 -> 0
C34: Bond issuer Fee (APV) | G34: =I34*$G$3 -> 0 | J34: 0
C35: Lender's Legal Fees | G35: =I35*$G$3 -> 0 | I35: 459.01639 | J35: =G35 -> 0
C36: Construction Period Real Estate Tax | G36: =I36*$G$3 -> 0 | I36: 622.95082 | J36: =G36 -> 0
C37: GL Insurance & BR Security during construction | G37: =I37*$G$3 -> 0 | I37: 2377.0492 | J37: =G37 -> 0
C38: Performance & Payment Bonds | G38: =I38*$G$3 -> 0 | I38: 4169.2657 | J38: =G38 -> 0
C39: Freddie TEL legal & Associated Fees | G39: =I39*$G$3 -> 0 | J39: =G39 -> 0
G40: =SUM(G31:G39) -> 0 | H40: =G40 -> 0 | J40: =SUM(J31:J39) -> 0
B41: Professional Services
C42: Architectural Fee - Design | G42: =I42*$G$3 -> 0 | I42: 2860.6557 | J42: =G42 -> 0
...

Sheet Rent Schedule
A1: Live Oak Manor Residences — Phase 1
A2: Maximum Eligible & Projected Rents | K2: 46111 | U2: =K26*D26 -> 0
H3: PBV rents are 110% of 2025 FMR Rents | N3: 1971.2 | U3: =U2*12 -> 0
A4: RENT ROLL | H4: LIHTC rents are 2025 rents per Novogradac
H5: Utility Allowances (UA) are based on JHA 1/25 schedule
A6: Unit Type | B6: Set-Aside | C6: Income Limit | D6: Number of Units | E6: Avg NRSF | F6: Max Eligible Gross Rent | G6: UA | H6: Net Rent | I6: $/NRSF | K6: Annual Rent | N6: 0 | O6: 0 | P6: 0 | U6: =U3*20 -> 0
A7: 1 BR | B7: 30% LIHTC | C7: 0.3 | H7: =F7-G7 -> 0 | I7: =IF(E7=0,0,H7/E7) -> 0 | K7: =H7*D7*12 -> 0 | L7: LIHTC
A8: 1 BR | B8: 50% LIHTC | C8: 0.5 | H8: =F8-G8 -> 0 | I8: =IF(E8=0,0,H8/E8) -> 0 | K8: =H8*D8*12 -> 0 | L8: LIHTC | N8: Total Required HAP Vouchers from HHA | R8: =D26 -> 0
A9: 1 BR | B9: 60% LIHTC | C9: 0.6 | H9: =F9-G9 -> 0 | I9: =IF(E9=0,0,H9/E9) -> 0 | K9: =H9*D9*12 -> 0 | L9: LIHTC | N9: HAP Voucher Payment Standard | S9: of HUD FMR rent
A10: 2 BR | B10: 30% LIHTC | C10: 0.3 | H10: =F10-G10 -> 0 | I10: =IF(E10=0,0,H10/E10) -> 0 | K10: =H10*D10*12 -> 0 | L10: LIHTC | N10: Total Affordable Units below 60% AMI | R10: {=D26-SUMPRODUCT((B7:B25="Market")*(D7:D25))} -> 0
A11: 2 BR | B11: 50% LIHTC | C11: 0.5 | H11: =F11-G11 -> 0 | I11: =IF(E11=0,0,H11/E11) -> 0 | K11: =H11*D11*12 -> 0 | L11: LIHTC | W11: 1248.5
A12: 2 BR | B12: 60% LIHTC | C12: 0.6 | H12: =F12-G12 -> 0 | I12: =IF(E12=0,0,H12/E12) -> 0 | K12: =H12*D12*12 -> 0 | L12: LIHTC | W12: 1492.7
A13: 3 BR | B13: 30% LIHTC | C13: 0.3 | H13: =F13-G13 -> 0 | I13: =IF(E13=0,0,H13/E13) -> 0 | K13: =H13*D13*12 -> 0 | L13: LIHTC | W13: 1971.2
A14: 3 BR | B14: 50% LIHTC | C14: 0.5 | H14: =F14-G14 -> 0 | I14: =IF(E14=0,0,H14/E14) -> 0 | K14: =H14*D14*12 -> 0 | L14: LIHTC | P14: {=SUMPRODUCT((C7:C25=0.3)*(D7:D25))} -> 0 | Q14: 30% PBV
A15: 3 BR | B15: 60% LIHTC | C15: 0.6 | H15: =F15-G15 -> 0 | I15: =IF(E15=0,0,H15/E15) -> 0 | K15: =H15*D15*12 -> 0 | L15: LIHTC | P15: {=SUMPRODUCT((C7:C25=0.5)*(D7:D25))} -> 0 | Q15: 50% PBV
A16: 4 BR | B16: 30% LIHTC | C16: 0.3 | H16: =F16-G16 -> 0 | I16: =IF(E16=0,0,H16/E16) -> 0 | K16: =H16*D16*12 -> 0 | L16: LIHTC | P16: {=SUMPRODUCT((C7:C25=0.6)*(D7:D25))} -> 0 | Q16: 60% PBV
A17: 4 BR | B17: 50% LIHTC | C17: 0.5 | H17: =F17-G17 -> 0 | I17: =IF(E17=0,0,H17/E17) -> 0 | K17: =H17*D17*12 -> 0 | L17: LIHTC | P17: 0 | Q17: 60% LIHTC
A18: 4 BR | B18: 60% LIHTC | C18: 0.6 | H18: =F18-G18 -> 0 | I18: =IF(E18=0,0,H18/E18) -> 0 | K18: =H18*D18*12 -> 0 | L18: LIHTC | P18: =D19 -> 0 | Q18: market
A19: Market | B19: Market | H19: =F19-G19 -> 0 | I19: =IF(E19=0,0,H19/E19) -> 0 | K19: =H19*D19*12 -> 0 | L19: Market
A26: TOTAL | D26: =SUM(D7:D25) -> 0 | E26: =IF(D26=0,0,SUMPRODUCT(D7:D25,E7:E25)/D26) -> 0 | H26: =IF(D26=0,0,SUMPRODUCT(D7:D25,H7:H25)/D26) -> 0 | K26: =SUM(K7:K25) -> 0 | L26: =IF(D26=0,0,K26/D26) -> 0 | P26: Target Total Distribution | U26: Actual Distribution by Unit Type
D27: 1
A28: Other Income | F28: Per Unit/Mo. | H28: All Units/Mo. | K28: Annual Revenue
A29: Laundry Machine Collections | H29: 0 | K29: =H29*D26*12 -> 0
A30: Late Fees | H30: 610 | K30: =H30*D26*12 -> 0
A31: Application Fees | H31: 305 | K31: =H31*D26*12 -> 0
A32: Security Deposit Forfeitures | H32: 122 | K32: =H32*D26*12 -> 0
A33: Other | H33: 122 | K33: =H33*D26*12 -> 0 | M33: 0.44185311
F34: 19 | H34: =SUM(H29:H33) -> 1159 | K34: =SUM(K29:K33) -> 0
A35: Commerical Space | E35: SF | H35: Monthly | I35: per SF/mo | J35: per year | K35: Annual Revenue
A36: Commercial Space | I36: 0 | J36: 0
A38: Subsidy Type | C38: Units | D38: Share | H38: Gross Potential Income | K38: =K26 -> 0
A39: PHA Sec 8 PBV-HAP | C39: {=SUMPRODUCT((LEFT(B7:B25,3)="PBV")*(D7:D25))} -> 0 | D39: =IF(C42=0,0,C39/C42) -> 0 | H39: Other Income | K39: =K34 -> 0
A40: LIHTC | C40: {=SUMPRODUCT((LEFT(B7:B25,1)<>"")*(LEFT(B7:B25,3)<>"PBV")*(LEFT(B7:B25,3)<>"Mar")*(D7:D25))} -> 0 | D40: =IF(C42=0,0,C40/C42) -> 0 | H40: Commercial Income per year | K40: =J36 -> 0
A41: Market Rate | C41: {=SUMPRODUCT((B7:B25="Market")*(D7:D25))} -> 0 | D41: =IF(C42=0,0,C41/C42) -> 0 | H41: Vacancy | J41: 0.07 | K41: =-(K38+K39+K40)*J41 -> 0
A42: Total | C42: =SUM(C39:C41) -> 0 | D42: =SUM(D39:D41) -> 0 | H42: Net Income | K42: =K38+K39+K40+K41 -> 0
A44: Unit Count | C44: 3 BR | D44: 4 BR | F44: Total | H44: % of Total | I44: % of LI
A45: 30% LIHTC | C45: {=SUMPRODUCT((C7:C25=0.3)*(LEFT(A7:A25,1)="3")*(D7:D25))} -> 0 | D45: {=SUMPRODUCT((C7:C25=0.3)*(LEFT(A7:A25,1)="4")*(D7:D25))} -> 0 | F45: =SUM(C45:E45) -> 0 | H45: =IF(F51=0,0,F45/F51) -> 0 | I45: =IF(F51=0,0,F45/(F51-F50)) -> 0
A46: 60% LIHTC | C46: {=SUMPRODUCT((C7:C25>=0.6)*(LEFT(A7:A25,1)="3")*(D7:D25))} -> 0 | D46: {=SUMPRODUCT((C7:C25>=0.6)*(LEFT(A7:A25,1)="4")*(D7:D25))} -> 0 | F46: =SUM(C46:E46) -> 0 | H46: =IF(F51=0,0,F46/F51) -> 0 | I46: =IF(F51=0,0,F46/(F51-F50)) -> 0
F47: =SUM(C47:E47) -> 0 | H47: =IF(F51=0,0,F47/F51) -> 0 | I47: =IF(F51=0,0,F47/(F51-F50)) -> 0
F48: =SUM(C48:E48) -> 0 | H48: =IF(F51=0,0,F48/F51) -> 0 | I48: =IF(F51=0,0,F48/(F51-F50)) -> 0
...

Sheet Operating Expense
A1: OPERATING BUDGET / EXPENSES | M1: LOR Feasibility Analysis Template
A2: Project Name | M2: 46111
N3: NOTE: Expenses updated. Do not match LHC application
E5: Project | J5: Average of Comparable Properties
A6: EXPENSES | F6: units | J6: 61 | K6: units
A8: OPERATING EXPENSES | E8: 2027 Baseline | F8: per unit | J8: bad debt | K8: 108.98292
J9: other admin | K9: 370.96086
A10: TOTAL ADMINISTRATIVE EXPENSES | E10: 0 | F10: 450 | J10: 29276.57 | K10: 479.94378
A11: TOTAL MARKETING EXPENSES | E11: 0 | F11: 200 | J11: 1743.7306 | K11: 28.585747
A12: TOTAL PAYROLL EXPENSES | E12: 0 | F12: 1803.2787 | J12: 64858.662 | K12: 1063.2567
A13: TOTAL MAINTENANCE EXPENSES | E13: 0 | F13: 1407.0492 | J13: 32366.195 | K13: 530.59337
A14: TOTAL CONTRACT EXPENSES | E14: 0 | F14: 675 | G14: * adjusted for security expense | J14: 41931.692 | K14: 687.40479
A15: TOTAL UTILITY EXPENSES | E15: 0 | F15: 1195.9016 | G15: *adjusted for tenant paid utilities | J15: 42065.069 | K15: 689.59129
A16: TOTAL MANAGEMENT AND PROFESSIONAL EXPENSES | E16: 0 | F16: 997.03279 | J16: 46358.912 | K16: 759.98216
A17: TOTAL TAXES AND INSURANCE | E17: 0 | F17: 2500 | G17: *adjusted for flood insurance where applicable | J17: 43882.8 | K17: 719.39016
A18: Bond Issuer Fee (Annually) | E18: 0 | F18: 0
B20: TOTAL EXPENSE | E20: 562924 | F20: 9228.2623 | J20: 302483.63 | K20: 4958.748
B21: Replacement Reserves | E21: 18300 | F21: 300
B22: TOTAL EXPENSE + Repl Res. | E22: 581224 | F22: 9528.2623
A24: Property Taxes | G24: per unit
A25: W/o Property Taxes or replacement reserves | E25: 562924 | F25: 9228.2623 | G25: per unit
A28: Net Revenue | E28: 942655.44 | H28: 46910.333
A29: Expense Ratio | E29: 0.59716836 | F29: <- may not exceed 65% per TDHCA
A30: NOI/Net Revenue | E30: 0.40283164
A37: OPERATING BUDGET / EXPENSES
A38: COMPARABLES
G40: 2026 Full Year | I40: 2026 Full Year | K40: 2026 Full Year | M40: 2026 Full Year | O40: 2026 Full Year | Q40: 2026 Full Year
G41: Property Name #1 | I41: Property Name #2 | K41: Property Name #3 | M41: Property Name #4 | O41: Property Name #5 | Q41: Property Name #6
A42: EXPENSES | H42: units | J42: units | K42: 270 | L42: units | M42: 330 | N42: units | P42: units | R42: units
A44: OPERATING EXPENSES
B46: Bad Debt Expense | H46: 0 | J46: 0 | K46: 47873.01 | L46: 177.30744 | M46: 49265 | N46: 149.28788 | P46: 82.265929 | R46: 245.03627
B47: All Other Admin Expense | G47: 96635.82 | H47: 483.1791 | I47: 115284.62 | J47: 603.5844 | K47: 79063.2 | L47: 292.82667 | M47: 71665.96 | N47: 217.16958 | O47: 35454.08 | P47: 253.24343 | Q47: 175105.08 | R47: 375.76197
A48: TOTAL ADMINISTRATIVE EXPENSES | G48: 96635.82 | H48: 483.1791 | I48: 115284.62 | J48: 603.5844 | K48: 126936.21 | L48: 470.13411 | M48: 120930.96 | N48: 366.45745 | O48: 46971.31 | P48: 335.50936 | Q48: 289291.98 | R48: 620.79824
A49: TOTAL MARKETING EXPENSES | H49: 0 | J49: 0 | K49: 7986.05 | L49: 29.577963 | M49: 10952.49 | N49: 33.189364 | P49: 50.733786 | R49: 58.013369
A50: TOTAL PAYROLL EXPENSES | H50: 0 | J50: 0 | K50: 376100.39 | L50: 1392.9644 | M50: 528359.88 | N50: 1601.0905 | O50: 206601.03 | P50: 1475.7216 | R50: 1909.7639
A51: TOTAL MAINTENANCE EXPENSES | H51: 0 | J51: 0 | K51: 203205.79 | L51: 752.61404 | M51: 205305.75 | N51: 622.13864 | P51: 869.56064 | R51: 939.24689
A52: TOTAL CONTRACT EXPENSES | H52: 0 | J52: 0 | K52: 258642.18 | L52: 957.934 | M52: 292920.98 | N52: 887.63933 | O52: 84763.73 | P52: 605.45521 | R52: 1673.4002
A53: TOTAL UTILITY EXPENSES | C53: net of water/sewer collection | G53: 128012.75 | H53: 640.06375 | I53: 141397.59 | J53: 740.30152 | K53: 124275.6 | L53: 460.28 | M53: 500882.87 | N53: 1517.8269 | O53: 43891.65 | P53: 313.51179 | Q53: 216952.74 | R53: 465.56382
A54: TOTAL MANAGEMENT & PROFESSIONAL EXPENSES | H54: 0 | J54: 0 | K54: 318097.01 | L54: 1178.1371 | M54: 413436.6 | N54: 1252.8382 | P54: 1059.7732 | R54: 1069.1445
A55: TOTAL TAX & INSURANCE EXPENSES* | H55: 0 | J55: 0 | K55: 277166.78 | L55: 1026.5436 | M55: 24333.7 | N55: 73.738485 | P55: 1457.8077 | R55: 1758.2512
...

Sheet 20yr Proforma
A1: SUMMARY PROFORMA | D1: 46111
A2: Development Name: | F2: [Project Name] | K2: 46111
C4: Year | F4: 1 | G4: 2 | H4: 3 | I4: 4 | J4: 5 | K4: 6 | L4: 7 | M4: 8 | N4: 9 | O4: 10 | P4: 11 | Q4: 12 | R4: 13 | S4: 14 | T4: 15 | U4: 16 | V4: 17 | W4: 18 | X4: 19 | Y4: 20
A5: Units: | C5: =_xlfn.SINGLE(TotalUnitCount) -> 61 | F5: Annual Income Growth Rate: | H5: 0.02 | I5: Vacancy Loss | K5: Annual Operating Expense/unit | M5: 9228.2623 | N5: * on sqr. foot basis | O5: LP Investor Asset Mgmt Fee: | R5: fee increases 3% per annum
A6: Total Rentable SF: | C6: ='Rent Schedule'!E26*'Rent Schedule'!D26 -> 0 | F6: Annual Expense Growth Rate: | K6: Annual Replacement Reserve/unit | M6: 300 | O6: Other Asset Mgmt. Fee: | R6: fee increases 3% per annum
A7: Stabilized Year 1 = | M7: 9528.2623 | O7: SLP Asset Mgt fee | R7: fee increases 3% per annum
F9: Year 1 | G9: Year 2 | H9: Year 3 | I9: Year 4 | J9: Year 5 | K9: Year 6 | L9: Year 7 | M9: Year 8 | N9: Year 9 | O9: Year 10 | P9: Year 11 | Q9: Year 12 | R9: Year 13 | S9: Year 14 | T9: Year 15 | U9: Year 16 | V9: Year 17 | W9: Year 18 | X9: Year 19 | Y9: Year 20
E10: baseline | G10: 2029 | H10: 2030 | I10: 2031 | J10: 2032 | K10: 2033 | L10: 2034 | M10: 2035 | N10: 2036 | O10: 2037 | P10: 2038 | Q10: 2039 | R10: 2040 | S10: 2041 | T10: 2042 | U10: 2043 | V10: 2044 | W10: 2045 | X10: 2046 | Y10: 2047
E11: * note that rents/expenses are trended from current levels
A12: Total Potential Rent Income | E12: ='Rent Schedule'!K26 -> 0 | F12: =E12*(1+$H$5) -> 0 | G12: =F12*(1+$H$5) -> 0 | H12: =G12*(1+$H$5) -> 0 | I12: =H12*(1+$H$5) -> 0 | J12: =I12*(1+$H$5) -> 0 | K12: =J12*(1+$H$5) -> 0 | L12: =K12*(1+$H$5) -> 0 | M12: =L12*(1+$H$5) -> 0 | ... Y12: =X12*(1+$H$5) -> 0
A13: ADD: | B13: Commercial + Other Income | E13: =K29+K30 -> 0 | F13: =E13*(1+$H$5) -> 0 | G13: =F13*(1+$H$5) -> 0 | H13: =G13*(1+$H$5) -> 0 | I13: =H13*(1+$H$5) -> 0 | J13: =I13*(1+$H$5) -> 0 | K13: =J13*(1+$H$5) -> 0 | L13: =K13*(1+$H$5) -> 0 | M13: =L13*(1+$H$5) -> 0 | ... Y13: =X13*(1+$H$5) -> 0
A15: Gross Potential Income | E15: =E12+E13 -> 0 | F15: =F12+F13 -> 0 | G15: =G12+G13 -> 0 | H15: =H12+H13 -> 0 | I15: =I12+I13 -> 0 | J15: =J12+J13 -> 0 | K15: =K12+K13 -> 0 | L15: =L12+L13 -> 0 | ... Y15: =Y12+Y13 -> 0
A17: LESS: | B17: Vacancy Allowance/Bad Debts/Concessions | E17: =E15*J5 -> 0 | F17: =F15*$J$5 -> 0 | G17: =G15*$J$5 -> 0 | H17: =H15*$J$5 -> 0 | I17: =I15*$J$5 -> 0 | J17: =J15*$J$5 -> 0 | K17: =K15*$J$5 -> 0 | L17: =L15*$J$5 -> 0 | M17: =M15*$J$5 -> 0 | ... Y17: =Y15*$J$5 -> 0
A19: Stabilized Income | E19: =E15-E17 -> 0 | F19: =F15-F17 -> 0 | G19: =G15-G17 -> 0 | H19: =H15-H17 -> 0 | I19: =I15-I17 -> 0 | J19: =J15-J17 -> 0 | K19: =K15-K17 -> 0 | L19: =L15-L17 -> 0 | ... Y19: =Y15-Y17 -> 0
A21: LESS: | B21: Operating Expenses | E21: ='Operating Expense'!H19 -> 0 | F21: =E21*(1+$I$5) -> #VALUE! | G21: =F21*(1+$I$5) -> #VALUE! | H21: =G21*(1+$I$5) -> #VALUE! | I21: =H21*(1+$I$5) -> #VALUE! | J21: =I21*(1+$I$5) -> #VALUE! | K21: =J21*(1+$I$5) -> #VALUE! | L21: =K21*(1+$I$5) -> #VALUE! | M21: =L21*(1+$I$5) -> #VALUE! | ... Y21: =X21*(1+$I$5) -> #VALUE!
A22: ADD: Property Tax Reduction | D22: yes | E22: 0 | F22: 0 | G22: 0 | H22: 0 | I22: 0 | J22: 0 | K22: 0 | L22: 0 | M22: 0 | N22: 0 | O22: 0 | P22: 0 | Q22: 0 | R22: 0 | S22: 0 | T22: 0 | U22: 0 | V22: 0 | W22: 0 | X22: 0 | Y22: 0
A23: LESS: | B23: Replacement Reserves | E23: ='Operating Expense'!H31 -> 0 | F23: =E23*(1+$I$5) -> #VALUE! | G23: =F23*(1+$I$5) -> #VALUE! | H23: =G23*(1+$I$5) -> #VALUE! | I23: =H23*(1+$I$5) -> #VALUE! | J23: =I23*(1+$I$5) -> #VALUE! | K23: =J23*(1+$I$5) -> #VALUE! | L23: =K23*(1+$I$5) -> #VALUE! | M23: =L23*(1+$I$5) -> #VALUE! | ... Y23: =X23*(1+$I$5) -> #VALUE!
A24: Net Operating Income | E24: =E19-E21+E22-E23 -> 0 | F24: =F19-F21+F22-F23 -> #VALUE! | G24: =G19-G21+G22-G23 -> #VALUE! | H24: =H19-H21+H22-H23 -> #VALUE! | I24: =I19-I21+I22-I23 -> #VALUE! | J24: =J19-J21+J22-J23 -> #VALUE! | K24: =K19-K21+K22-K23 -> #VALUE! | L24: =L19-L21+L22-L23 -> #VALUE! | ... Y24: =Y19-Y21+Y22-Y23 -> #VALUE!
B26: SCHEDULED DEBT SERVICE:
A27: LESS: | B27: Debt Service 1st | E27: =IFERROR(#REF!,0) -> 0 | F27: =IFERROR(#REF!,0) -> 0 | G27: =F27 -> 0 | H27: =G27 -> 0 | I27: =H27 -> 0 | J27: =I27 -> 0 | K27: =J27 -> 0 | L27: =K27 -> 0 | M27: =L27 -> 0 | N27: =M27 -> 0 | ... Y27: =X27 -> 0
B28: Debt Service 2nd | E28: =IFERROR(#REF!,0) -> 0 | F28: =IFERROR(#REF!,0) -> 0 | G28: =F28 -> 0 | H28: =G28 -> 0 | I28: =H28 -> 0 | J28: =I28 -> 0 | K28: =J28 -> 0 | L28: =K28 -> 0 | M28: =L28 -> 0 | N28: =M28 -> 0 | ... Y28: =X28 -> 0
B29: Debt Service 3rd | E29: =IFERROR(#REF!,0) -> 0 | F29: =IFERROR(#REF!,0) -> 0 | G29: =F29 -> 0 | H29: =G29 -> 0 | I29: =H29 -> 0 | J29: =I29 -> 0 | K29: =J29 -> 0 | L29: =K29 -> 0 | M29: =L29 -> 0 | N29: =M29 -> 0 | ... Y29: =X29 -> 0
B30: Debt Service 4th | E30: 0 | F30: =IFERROR(#REF!,0) -> 0 | G30: =F30 -> 0 | H30: =G30 -> 0 | I30: =H30 -> 0 | J30: =I30 -> 0 | K30: =J30 -> 0 | L30: =K30 -> 0 | M30: =L30 -> 0 | N30: =M30 -> 0 | ... Y30: =X30 -> 0
B31: Debt Service 5th | E31: 0 | F31: =IFERROR(#REF!,0) -> 0 | G31: =F31 -> 0 | H31: =G31 -> 0 | I31: =H31 -> 0 | J31: =I31 -> 0 | K31: =J31 -> 0 | L31: =K31 -> 0 | M31: =L31 -> 0 | N31: =M31 -> 0 | ... Y31: =X31 -> 0
B32: Debt Service 6th
C33: deferred fee note | E33: 12 | F33: =F39+F41 -> #VALUE! | G33: =G39+G41 -> #VALUE! | H33: =H39+H41 -> #VALUE! | I33: =I39+I41 -> #VALUE! | J33: =J39+J41 -> #VALUE! | K33: =K39+K41 -> #VALUE! | L33: =L39+L41 -> #VALUE! | M33: =M39+M41 -> #VALUE! | ... Y33: =Y39+Y41 -> #VALUE!
A35: Operating Cash Flow Waterfall:
B36: Net Operating Income: | E36: =E24 -> 0 | F36: =F24 -> #VALUE! | G36: =G24 -> #VALUE! | H36: =H24 -> #VALUE! | I36: =I24 -> #VALUE! | J36: =J24 -> #VALUE! | K36: =K24 -> #VALUE! | L36: =L24 -> #VALUE! | ... Y36: =Y24 -> #VALUE!
B37: (less) First mortgage debt | E37: =-E27 -> 0 | F37: =-F27 -> 0 | G37: =-G27 -> 0 | H37: =-H27 -> 0 | I37: =-I27 -> 0 | J37: =-J27 -> 0 | K37: =-K27 -> 0 | L37: =-L27 -> 0 | ... Y37: =-Y27 -> 0
B38: (less) Second mortgage debt_HHA | E38: =-E28 -> 0 | F38: =-F28 -> 0 | G38: =-G28 -> 0 | H38: =-H28 -> 0 | I38: =-I28 -> 0 | J38: =-J28 -> 0 | K38: =-K28 -> 0 | L38: =-L28 -> 0 | ... Y38: =-Y28 -> 0
B39: Cash Flow after 1st Mortg Debt: | E39: =E36+E37+E38 -> 0 | F39: =F36+F37+F38 -> #VALUE! | G39: =G36+G37+G38 -> #VALUE! | H39: =H36+H37+H38 -> #VALUE! | I39: =I36+I37+I38 -> #VALUE! | J39: =J36+J37+J38 -> #VALUE! | K39: =K36+K37+K38 -> #VALUE! | L39: =L36+L37+L38 -> #VALUE! | ... Y39: =Y36+Y37+Y38 -> #VALUE!
B41: (less) Investor LP Asset Mgmt fee | E41: from cash flow | F41: =-F82 -> -8500 | G41: =-G82 -> #VALUE! | H41: =-H82 -> #VALUE! | I41: =-I82 -> #VALUE! | J41: =-J82 -> #VALUE! | K41: =-K82 -> #VALUE! | L41: =-L82 -> #VALUE! | M41: =-M82 -> #VALUE! | ... Y41: =-Y82 -> #VALUE!
B42: (less) payment to DDF | E42: from cash flow -to P&I | F42: =-IF(SUM(F39:F41)>0,MIN(SUM(F39:F41),F63),0) -> #VALUE! | G42: =-IF(SUM(G39:G41)>0,MIN(SUM(G39:G41),G63),0) -> #VALUE! | H42: =-IF(SUM(H39:H41)>0,MIN(SUM(H39:H41),H63),0) -> #VALUE! | I42: =-IF(SUM(I39:I41)>0,MIN(SUM(I39:I41),I63),0) -> #VALUE! | J42: =-IF(SUM(J39:J41)>0,MIN(SUM(J39:J41),J63),0) -> #VALUE! | K42: =-IF(SUM(K39:K41)>0,MIN(SUM(K39:K41),K63),0) -> #VALUE! | L42: =-IF(SUM(L39:L41)>0,MIN(SUM(L39:L41),L63),0) -> #VALUE! | M42: =-IF(SUM(M39:M41)>0,MIN(SUM(M39:M41),M63),0) -> #VALUE! | ... Y42: =-IF(SUM(Y39:Y41)>0,MIN(SUM(Y39:Y41),Y63),0) -> #VALUE!
B43: (less) SLP Asset Mgmt fee-Columbia SLP | E43: from cash flow | F43: 0 | G43: 0 | H43: 0 | I43: 0 | J43: 0 | K43: 0 | L43: 0 | M43: 0 | N43: 0 | O43: 0 | P43: 0 | Q43: 0 | R43: 0 | S43: 0 | T43: 0 | U43: 0 | V43: 0 | W43: 0 | X43: 0 | Y43: 0
B44: (less) Cash Flow to Investor LP | E44: from cash flow | F44: 0 | G44: 0 | H44: 0 | I44: 0 | J44: 0 | K44: 0 | L44: 0 | M44: 0 | N44: 0 | O44: 0 | P44: 0 | Q44: 0 | R44: 0 | S44: 0 | T44: 0 | U44: 0 | V44: 0 | W44: 0 | X44: 0 | Y44: 0
B45: (less) Cashflow to GP/SLP | E45: from cash flow | F45: 0 | G45: 0 | H45: 0 | I45: 0 | J45: 0 | K45: 0 | L45: 0 | M45: 0 | N45: 0 | O45: 0 | P45: 0 | Q45: 0 | R45: 0 | S45: 0 | T45: 0 | U45: 0 | V45: 0 | W45: 0 | X45: 0 | Y45: 0
B46: (less) Incentive Mgmt Fee to GP/SLP | E46: from cash flow | F46: 0 | G46: 0 | H46: 0 | I46: 0 | J46: 0 | K46: 0 | L46: 0 | M46: 0 | N46: 0 | O46: 0 | P46: 0 | Q46: 0 | R46: 0 | S46: 0 | T46: 0 | U46: 0 | V46: 0 | W46: 0 | X46: 0 | Y46: 0
B47: (less) 2nd mortgage debt-HHA | E47: from cash flow -to P&I | F47: =#REF!+#REF! -> #REF! | G47: =F47 -> #REF! | H47: =G47 -> #REF! | I47: =H47 -> #REF! | J47: =I47 -> #REF! | K47: =J47 -> #REF! | L47: =K47 -> #REF! | M47: =L47 -> #REF! | N47: =M47 -> #REF! | ... Y47: =X47 -> #REF!
B48: (less) | E48: from cash flow -to P&I | F48: 0 | G48: 0 | H48: 0 | I48: 0 | J48: 0 | K48: 0 | L48: 0 | M48: 0 | N48: 0 | O48: 0 | P48: 0 | Q48: 0 | R48: 0 | S48: 0 | T48: 0 | U48: 0 | V48: 0 | W48: 0 | X48: 0 | Y48: 0
B49: Net Cash Flow | E49: =SUM(E39:E48) -> 0 | F49: =SUM(F39:F48) -> #VALUE! | G49: =SUM(G39:G48) -> #VALUE! | H49: =SUM(H39:H48) -> #VALUE! | I49: =SUM(I39:I48) -> #VALUE! | J49: =SUM(J39:J48) -> #VALUE! | K49: =SUM(K39:K48) -> #VALUE! | L49: =SUM(L39:L48) -> #VALUE! | ... Y49: =SUM(Y39:Y48) -> #VALUE!
...

Sheet Credit Delivery & Pay-Ins
B1: Project Name | G1: RipeSpot Feasibility Analysis Template
C3: Credit Allocation (annual): | F3: 0 | J3: Annual Credits (allocation): | N3: 0 | P3: Closing
C4: Total Units: | F4: 0 | J4: Syndicator Percentage: | N4: 0.9999 | P4: Construction
C5: LIHTC Units: | J5: Equity Pricing (per credit): | N5: 0 | P5: Completion
C6: Cred Factor | F6: 0
K7: Total Equity Pay-In | N7: 0 | P7: Absorbtion Rate
B8: LEASE-UP / CREDIT DELIVERY SCHEDULE
C9: LIHTC Units Only
B10: Year | C10: Units Leased | D10: Cumulative | E10: Tax Credit | F10: Monthly | I10: EQUITY PAY-IN SCHEDULE
B11: 2027 | C11: In Month | D11: Leased | E11: Factor | F11: Credits | K11: Month | L11: Milestone | M11: % complete | N11: Federal | O11: State | P11: total | Q11: % of total
B12: January | D12: 0 | F12: 0 | H12: 45658 | J12: January
B13: February | D13: 0 | F13: 0 | H13: 45689 | J13: February
B14: March | D14: 0 | F14: 0 | H14: 45717 | J14: March
B15: April | D15: 0 | F15: 0 | H15: 45748 | J15: April
B16: May | D16: 0 | F16: 0 | H16: 45778 | J16: May
B17: June | D17: 0 | F17: 0 | H17: 45809 | J17: June
B18: July | D18: 0 | F18: 0 | H18: 45839 | J18: July
B19: August | D19: 0 | F19: 0 | H19: 45870 | J19: August
B20: September | D20: 0 | F20: 0 | H20: 45901 | J20: September
B21: October | D21: 0 | F21: 0 | H21: 45931 | J21: October
B22: November | D22: 0 | F22: 0 | H22: 45962 | J22: November | L22: CLOSING | N22: 0
B23: December | D23: 0 | F23: 0 | H23: 45992 | J23: December | K23: 1
B24: Totals: | C24: 0 | D24: 0 | F24: 0 | H24: 46023 | I24: 2026 | J24: January | K24: 2
H25: 46054 | J25: February | K25: 3
H26: 46082 | J26: March | K26: 4
B27: Year | C27: Units Leased | D27: Cumulative | E27: Tax Credit | F27: Monthly | H27: 46113 | J27: April | K27: 5
B28: 2028 | C28: In Month | D28: Leased | E28: Factor | F28: Credits | H28: 46143 | J28: May | K28: 6
B29: January | D29: 0 | E29: 1159.7834 | F29: 0 | H29: 46174 | J29: June | K29: 7
B30: February | D30: 0 | E30: 1159.7834 | F30: 0 | H30: 46204 | J30: July | K30: 8
B31: March | D31: 0 | E31: 1159.7834 | F31: 0 | H31: 46235 | J31: August | K31: 9
B32: April | D32: 0 | E32: 1159.7834 | F32: 0 | H32: 46266 | J32: September | K32: 10
B33: May | D33: 0 | E33: 1159.7834 | F33: 0 | H33: 46296 | J33: October | K33: 11 | L33: 50% complete | N33: 0
B34: June | D34: 0 | E34: 1159.7834 | F34: 0 | H34: 46327 | J34: November | K34: 12
B35: July | D35: 0 | E35: 1159.7834 | F35: 0 | H35: 46357 | J35: December | K35: 13
B36: August | D36: 0 | E36: 1159.7834 | F36: 0 | H36: 46388 | I36: 2027 | J36: January | K36: 14
B37: September | D37: 0 | E37: 1159.7834 | F37: 0 | H37: 46419 | J37: February | K37: 15
B38: October | D38: 0 | E38: 1159.7834 | F38: 0 | H38: 46447 | J38: March | K38: 16
B39: November | D39: 0 | E39: 1159.7834 | F39: 0 | H39: 46478 | J39: April | K39: 17
B40: December | D40: 0 | E40: 1159.7834 | F40: 0 | H40: 46508 | J40: May | K40: 18
B41: Totals: | C41: 0 | D41: 0 | F41: 0 | H41: 46539 | J41: June | K41: 19
...

Sheet Flow of Funds
B1: FLOW OF FUNDS | G1: RipeSpot Feasibility Analysis Template
B2: [Project Name] | H2: 0 | I2: 1 | J2: 2 | K2: 3 | L2: 4 | M2: 5 | N2: 6 | O2: 7 | P2: 8 | Q2: 9 | R2: 10 | S2: 11 | T2: 12 | U2: 13 | V2: 14 | W2: 15 | X2: 16 | Y2: 17 | Z2: 18 | AA2: 19 | AB2: 20 | AC2: 21 | AD2: 22 | AE2: 23 | AF2: 24 | AG2: 25 | AH2: 26 | AI2: 27 | AJ2: 28 | AK2: 29 | AL2: 30 | AM2: 31 | AN2: 32 | AO2: 33 | AP2: 34 | AQ2: 35 | AR2: 36 | AS2: 37 | AT2: 38 | AU2: 39
B3: Units | I3: 45992 | J3: 46023 | K3: 46054 | L3: 46082 | M3: 46113 | N3: 46143 | O3: 46174 | P3: 46204 | Q3: 46235 | R3: 46266 | S3: 46296 | T3: 46327 | U3: 46357 | V3: 46388 | W3: 46419 | X3: 46447 | Y3: 46478 | Z3: 46508 | AA3: 46539 | AB3: 46569 | AC3: 46600 | AD3: 46631 | AE3: 46661 | AF3: 46692 | AG3: 46722 | AH3: 46753 | AI3: 46784 | AJ3: 46813 | AK3: 46844 | AL3: 46874 | AM3: 46905 | AN3: 46935 | AO3: 46966 | AP3: 46997 | AQ3: 47027 | AR3: 47058 | AS3: 47088 | AT3: 47119 | AU3: 47150
F4: Total | G4: Expended | H4: Closing | I4: Construction Start----------> | S4: 50% Completion | AD4: 100% Complete | AE4: Constr Completion | AR4: Stabilization | AV4: Total Drawn | AW4: Variance
A5: SOURCES | AD5: 2nd Installment | AE5: 2nd Installment | AR5: 3rd Installment
B6: Tax Exempt Bonds | E6: 0 | F6: ='Perm Sources-Uses'!K67 -> 0 | G6: 0 | H6: 0 | I6: 0 | J6: 0 | K6: 0 | L6: 0 | M6: 0 | N6: 0 | O6: 0 | P6: 0 | Q6: 0 | R6: 0 | S6: 0 | T6: 0 | U6: 0 | V6: 0 | W6: 0 | X6: 0 | Y6: 0 | Z6: 0 | AA6: 0 | AB6: 0 | AC6: 0 | AD6: 0 | AE6: 0 | AF6: 0 | AG6: 0 | AH6: 0 | AI6: 0 | AJ6: 0 | AK6: 0 | AL6: 0 | AM6: 0 | AN6: 0 | AO6: 0 | AP6: 0 | AQ6: 0 | AR6: 0 | AS6: 0 | AT6: 0 | AU6: 0 | AV6: 0 | AW6: 0
B7: ='Perm Sources-Uses'!K68 -> 0 | E7: 0 | F7: ='Perm Sources-Uses'!K68 -> 0 | G7: 0 | H7: 0 | I7: 0 | J7: 0 | K7: 0 | L7: 0 | M7: 0 | N7: 0 | O7: 0 | P7: 0 | Q7: 0 | R7: 0 | S7: 0 | T7: 0 | U7: 0 | V7: 0 | W7: 0 | X7: 0 | Y7: 0 | Z7: 0 | AA7: 0 | AB7: 0 | AC7: 0 | AD7: 0 | AE7: 0 | AF7: 0 | AG7: 0 | AH7: 0 | AI7: 0 | AJ7: 0 | AK7: 0 | AL7: 0 | AM7: 0 | AN7: 0 | AO7: 0 | AP7: 0 | AQ7: 0 | AR7: 0 | AS7: 0 | AT7: 0 | AU7: 0 | AV7: =SUM(H7:AU7) -> 0 | AW7: =F7-AV7 -> 0
B8: First Mortgage | D8: =IF(F16=0,0,F8/F16) -> 0 | E8: 0 | F8: ='Perm Sources-Uses'!E8 -> 0 | G8: 0 | H8: 0 | I8: 0 | J8: 0 | K8: 0 | L8: 0 | M8: 0 | N8: 0 | O8: 0 | P8: 0 | Q8: 0 | R8: 0 | S8: 0 | T8: 0 | U8: 0 | V8: 0 | W8: 0 | X8: 0 | Y8: 0 | Z8: 0 | AA8: 0 | AB8: 0 | AC8: 0 | AD8: 0 | AE8: 0 | AF8: 0 | AG8: 0 | AH8: 0 | AI8: 0 | AJ8: 0 | AK8: 0 | AL8: 0 | AM8: 0 | AN8: 0 | AO8: 0 | AP8: 0 | AQ8: 0 | AR8: 0 | AS8: 0 | AT8: 0 | AU8: 0 | AV8: =SUM(H8:AU8) -> 0 | AW8: =F8-AV8 -> 0
B9: 2nd Mortgage | D9: =IF(F16=0,0,F9/F16) -> 0 | E9: 0 | F9: ='Perm Sources-Uses'!E9 -> 0 | G9: 0 | H9: 0 | I9: 0 | J9: 0 | K9: 0 | L9: 0 | M9: 0 | N9: 0 | O9: 0 | P9: 0 | Q9: 0 | R9: 0 | S9: 0 | T9: 0 | U9: 0 | V9: 0 | W9: 0 | X9: 0 | Y9: 0 | Z9: 0 | AA9: 0 | AB9: 0 | AC9: 0 | AD9: 0 | AE9: 0 | AF9: 0 | AG9: 0 | AH9: 0 | AI9: 0 | AJ9: 0 | AK9: 0 | AL9: 0 | AM9: 0 | AN9: 0 | AO9: 0 | AP9: 0 | AQ9: 0 | AR9: 0 | AS9: 0 | AT9: 0 | AU9: 0 | AV9: =SUM(H9:AU9) -> 0 | AW9: =F9-AV9 -> 0
B10: 3rd Mortgage | D10: =IF(F16=0,0,F10/F16) -> 0 | E10: 0 | F10: ='Perm Sources-Uses'!E10 -> 0 | G10: 0 | H10: 0 | I10: 0 | J10: 0 | K10: 0 | L10: 0 | M10: 0 | N10: 0 | O10: 0 | P10: 0 | Q10: 0 | R10: 0 | S10: 0 | T10: 0 | U10: 0 | V10: 0 | W10: 0 | X10: 0 | Y10: 0 | Z10: 0 | AA10: 0 | AB10: 0 | AC10: 0 | AD10: 0 | AE10: 0 | AF10: 0 | AG10: 0 | AH10: 0 | AI10: 0 | AJ10: 0 | AK10: 0 | AL10: 0 | AM10: 0 | AN10: 0 | AO10: 0 | AP10: 0 | AQ10: 0 | AR10: 0 | AS10: 0 | AT10: 0 | AU10: 0 | AV10: =SUM(H10:AU10) -> 0 | AW10: =F10-AV10 -> 0
B11: L.P. Capital Contribution | D11: =IF(F16=0,0,F11/F16) -> 0 | E11: 0 | F11: ='Perm Sources-Uses'!E15 -> 0 | G11: 0 | H11: 0 | I11: 0 | J11: 0 | K11: 0 | L11: 0 | M11: 0 | N11: 0 | O11: 0 | P11: 0 | Q11: 0 | R11: 0 | S11: 0 | T11: 0 | U11: 0 | V11: 0 | W11: 0 | X11: 0 | Y11: 0 | Z11: 0 | AA11: 0 | AB11: 0 | AC11: 0 | AD11: 0 | AE11: 0 | AF11: 0 | AG11: 0 | AH11: 0 | AI11: 0 | AJ11: 0 | AK11: 0 | AL11: 0 | AM11: 0 | AN11: 0 | AO11: 0 | AP11: 0 | AQ11: 0 | AR11: 0 | AS11: 0 | AT11: 0 | AU11: 0 | AV11: =SUM(H11:AU11) -> 0 | AW11: =F11-AV11 -> 0
B12: GAP | D12: =IF(F16=0,0,F12/F16) -> 0 | E12: 0 | F12: ='Perm Sources-Uses'!E12 -> 0 | G12: 0 | H12: 0 | I12: 0 | J12: 0 | K12: 0 | L12: 0 | M12: 0 | N12: 0 | O12: 0 | P12: 0 | Q12: 0 | R12: 0 | S12: 0 | T12: 0 | U12: 0 | V12: 0 | W12: 0 | X12: 0 | Y12: 0 | Z12: 0 | AA12: 0 | AB12: 0 | AC12: 0 | AD12: 0 | AE12: 0 | AF12: 0 | AG12: 0 | AH12: 0 | AI12: 0 | AJ12: 0 | AK12: 0 | AL12: 0 | AM12: 0 | AN12: 0 | AO12: 0 | AP12: 0 | AQ12: 0 | AR12: 0 | AS12: 0 | AT12: 0 | AU12: 0 | AV12: =SUM(H12:AU12) -> 0 | AW12: =F12-AV12 -> 0
B13: Bond Arbitrage Earnings | D13: =IF(F16=0,0,F13/F16) -> 0 | E13: 0 | F13: ='Perm Sources-Uses'!E18 -> 0 | G13: 0 | H13: 0 | I13: 0 | J13: 0 | K13: 0 | L13: 0 | M13: 0 | N13: 0 | O13: 0 | P13: 0 | Q13: 0 | R13: 0 | S13: 0 | T13: 0 | U13: 0 | V13: 0 | W13: 0 | X13: 0 | Y13: 0 | Z13: 0 | AA13: 0 | AB13: 0 | AC13: 0 | AD13: 0 | AE13: 0 | AF13: 0 | AG13: 0 | AH13: 0 | AI13: 0 | AJ13: 0 | AK13: 0 | AL13: 0 | AM13: 0 | AN13: 0 | AO13: 0 | AP13: 0 | AQ13: 0 | AR13: 0 | AS13: 0 | AT13: 0 | AU13: 0 | AV13: =SUM(H13:AU13) -> 0 | AW13: =F13-AV13 -> 0
B14: 45L Credits | D14: =IF(F16=0,0,F14/F16) -> 0 | E14: 0 | F14: ='Perm Sources-Uses'!E13 -> 0 | G14: 0 | H14: 0 | I14: 0 | J14: 0 | K14: 0 | L14: 0 | M14: 0 | N14: 0 | O14: 0 | P14: 0 | Q14: 0 | R14: 0 | S14: 0 | T14: 0 | U14: 0 | V14: 0 | W14: 0 | X14: 0 | Y14: 0 | Z14: 0 | AA14: 0 | AB14: 0 | AC14: 0 | AD14: 0 | AE14: 0 | AF14: 0 | AG14: 0 | AH14: 0 | AI14: 0 | AJ14: 0 | AK14: 0 | AL14: 0 | AM14: 0 | AN14: 0 | AO14: 0 | AP14: 0 | AQ14: 0 | AR14: 0 | AS14: 0 | AT14: 0 | AU14: 0 | AV14: =SUM(H14:AU14) -> 0 | AW14: =F14-AV14 -> 0
B15: Deferred Developer Fee | D15: =IF(F16=0,0,F15/F16) -> 0 | E15: 0 | F15: ='Perm Sources-Uses'!E17 -> 0 | G15: 0 | H15: 0 | I15: 0 | J15: 0 | K15: 0 | L15: 0 | M15: 0 | N15: 0 | O15: 0 | P15: 0 | Q15: 0 | R15: 0 | S15: 0 | T15: 0 | U15: 0 | V15: 0 | W15: 0 | X15: 0 | Y15: 0 | Z15: 0 | AA15: 0 | AB15: 0 | AC15: 0 | AD15: 0 | AE15: 0 | AF15: 0 | AG15: 0 | AH15: 0 | AI15: 0 | AJ15: 0 | AK15: 0 | AL15: 0 | AM15: 0 | AN15: 0 | AO15: 0 | AP15: 0 | AQ15: 0 | AR15: 0 | AS15: 0 | AT15: 0 | AU15: 0 | AV15: =SUM(H15:AU15) -> 0 | AW15: =F15-AV15 -> 0
C16: Total Sources: | E16: 0 | F16: =SUM(F7:F15) -> 0 | G16: =SUM(G7:G15) -> 0 | H16: =SUM(H7:H15) -> 0 | I16: =SUM(I7:I15) -> 0 | J16: =SUM(J7:J15) -> 0 | K16: =SUM(K7:K15) -> 0 | L16: =SUM(L7:L15) -> 0 | M16: =SUM(M7:M15) -> 0 | ... AW16: =SUM(AW7:AW15) -> 0
E17: % of Equity Capital | G17: 0 | H17: 0.15 | I17: 0 | J17: 0 | K17: 0 | L17: 0 | M17: 0 | N17: 0 | O17: 0 | P17: 0 | Q17: 0 | R17: 0 | S17: 0.25 | T17: 0 | U17: 0 | V17: 0 | W17: 0 | X17: 0 | Y17: 0 | Z17: 0 | AA17: 0 | AB17: 0 | AC17: 0 | AD17: 0.25 | AE17: 0 | AF17: 0 | AG17: 0 | AH17: 0.1 | AI17: 0 | AJ17: 0.1 | AK17: 0 | AL17: 0 | AM17: 0 | AN17: 0 | AO17: 0 | AP17: 0.1 | AQ17: 0.05 | AR17: 0.3598 | AT17: 0 | AU17: 0 | AV17: 0 | AW17: 0
E18: 0 | G18: 0 | AV18: 0 | AW18: 0
A19: USES | E19: 0 | F19: 0 | G19: 0 | H19: 0 | I19: 0 | J19: 0 | K19: 0 | L19: 0 | M19: 0 | N19: 0 | O19: 0 | P19: 0 | Q19: 0 | R19: 0 | S19: 0 | T19: 0 | U19: 0 | V19: 0 | W19: 0 | X19: 0 | Y19: 0 | Z19: 0 | AA19: 0 | AB19: 0 | AC19: 0 | AD19: 0 | AE19: 0 | AF19: 0 | AG19: 0 | AH19: 0 | AI19: 0 | AJ19: 0 | AK19: 0 | AL19: 0 | AM19: 0 | AN19: 0 | AO19: 0 | AP19: 0 | AQ19: 0 | AR19: 0 | AS19: 0 | AT19: 0 | AU19: 0 | AV19: 0 | AW19: 0
A20: Acquisition Costs | E20: 0 | F20: 0 | G20: 0 | H20: 0 | I20: 0 | J20: 0 | K20: 0 | L20: 0 | M20: 0 | N20: 0 | O20: 0 | P20: 0 | Q20: 0 | R20: 0 | S20: 0 | T20: 0 | U20: 0 | V20: 0 | W20: 0 | X20: 0 | Y20: 0 | Z20: 0 | AA20: 0 | AB20: 0 | AC20: 0 | AD20: 0 | AE20: 0 | AF20: 0 | AG20: 0 | AH20: 0 | AI20: 0 | AJ20: 0 | AK20: 0 | AL20: 0 | AM20: 0 | AN20: 0 | AO20: 0 | AP20: 0 | AQ20: 0 | AR20: 0 | AS20: 0 | AT20: 0 | AU20: 0 | AV20: 0 | AW20: 0
B21: Land/Ground Lease Prepayment | E21: 0 | F21: ='Development Budget'!G9 -> 0 | G21: 0 | H21: 0 | I21: 0 | J21: 0 | K21: 0 | L21: 0 | M21: 0 | N21: 0 | O21: 0 | P21: 0 | Q21: 0 | R21: 0 | S21: 0 | T21: 0 | U21: 0 | V21: 0 | W21: 0 | X21: 0 | Y21: 0 | Z21: 0 | AA21: 0 | AB21: 0 | AC21: 0 | AD21: 0 | AE21: 0 | AF21: 0 | AG21: 0 | AH21: 0 | AI21: 0 | AJ21: 0 | AK21: 0 | AL21: 0 | AM21: 0 | AN21: 0 | AO21: 0 | AP21: 0 | AQ21: 0 | AR21: 0 | AS21: 0 | AT21: 0 | AU21: 0 | AV21: =SUM(H21:AU21) -> 0 | AW21: =F21-AV21 -> 0
E22: 0 | F22: 0 | G22: 0 | H22: 0 | I22: 0 | J22: 0 | K22: 0 | L22: 0 | M22: 0 | N22: 0 | O22: 0 | P22: 0 | Q22: 0 | R22: 0 | S22: 0 | T22: 0 | U22: 0 | V22: 0 | W22: 0 | X22: 0 | Y22: 0 | Z22: 0 | AA22: 0 | AB22: 0 | AC22: 0 | AD22: 0 | AE22: 0 | AF22: 0 | AG22: 0 | AH22: 0 | AI22: 0 | AJ22: 0 | AK22: 0 | AL22: 0 | AM22: 0 | AN22: 0 | AO22: 0 | AP22: 0 | AQ22: 0 | AR22: 0 | AS22: 0 | AT22: 0 | AU22: 0 | AV22: 0 | AW22: 0
A23: Construction Costs | F23: 0 | G23: 0 | H23: 0 | I23: 0 | J23: 0 | K23: 0 | L23: 0 | M23: 0 | N23: 0 | O23: 0 | P23: 0 | Q23: 0 | R23: 0 | S23: 0 | T23: 0 | U23: 0 | V23: 0 | W23: 0 | X23: 0 | Y23: 0 | Z23: 0 | AA23: 0 | AB23: 0 | AC23: 0 | AD23: 0 | AE23: 0 | AF23: 0 | AG23: 0 | AH23: 0 | AI23: 0 | AJ23: 0 | AK23: 0 | AL23: 0 | AM23: 0 | AN23: 0 | AO23: 0 | AP23: 0 | AQ23: 0 | AR23: 0 | AS23: 0 | AT23: 0 | AU23: 0 | AV23: 0 | AW23: 0
B24: Hard Costs | D24: 23.27 | E24: 0 | F24: ='Development Budget'!G12 -> 0 | G24: 0 | H24: 0 | I24: 0 | J24: 0 | K24: 0 | L24: 0 | M24: 0 | N24: 0 | O24: 0 | P24: 0 | Q24: 0 | R24: 0 | S24: 0 | T24: 0 | U24: 0 | V24: 0 | W24: 0 | X24: 0 | Y24: 0 | Z24: 0 | AA24: 0 | AB24: 0 | AC24: 0 | AD24: 0 | AE24: 0 | AF24: 0 | AG24: 0 | AH24: 0 | AI24: 0 | AJ24: 0 | AK24: 0 | AL24: 0 | AM24: 0 | AN24: 0 | AO24: 0 | AP24: 0 | AQ24: 0 | AR24: 0 | AS24: 0 | AT24: 0 | AU24: 0 | AV24: =SUM(H24:AU24) -> 0 | AW24: =F24-AV24 -> 0
B25: Sitework & Related Fees | E25: 0 | F25: ='Development Budget'!G13 -> 0 | G25: 0 | H25: 0 | I25: 0 | J25: 0 | K25: 0 | L25: 0 | M25: 0 | N25: 0 | O25: 0 | P25: 0 | Q25: 0 | R25: 0 | S25: 0 | T25: 0 | U25: 0 | V25: 0 | W25: 0 | X25: 0 | Y25: 0 | Z25: 0 | AA25: 0 | AB25: 0 | AC25: 0 | AD25: 0 | AE25: 0 | AF25: 0 | AG25: 0 | AH25: 0 | AI25: 0 | AJ25: 0 | AK25: 0 | AL25: 0 | AM25: 0 | AN25: 0 | AO25: 0 | AP25: 0 | AQ25: 0 | AR25: 0 | AS25: 0 | AT25: 0 | AU25: 0 | AV25: =SUM(H25:AU25) -> 0 | AW25: =F25-AV25 -> 0
B26: Structured Parking | E26: 0 | F26: ='Development Budget'!G14 -> 0 | G26: 0 | H26: 0 | I26: 0 | J26: 0 | K26: 0 | L26: 0 | M26: 0 | N26: 0 | O26: 0 | P26: 0 | Q26: 0 | R26: 0 | S26: 0 | T26: 0 | U26: 0 | V26: 0 | W26: 0 | X26: 0 | Y26: 0 | Z26: 0 | AA26: 0 | AB26: 0 | AC26: 0 | AD26: 0 | AE26: 0 | AF26: 0 | AG26: 0 | AH26: 0 | AI26: 0 | AJ26: 0 | AK26: 0 | AL26: 0 | AM26: 0 | AN26: 0 | AO26: 0 | AP26: 0 | AQ26: 0 | AR26: 0 | AS26: 0 | AT26: 0 | AU26: 0 | AV26: =SUM(H26:AU26) -> 0 | AW26: =F26-AV26 -> 0
B27: Utility Connection Fees | E27: 0 | F27: ='Development Budget'!G15 -> 0 | G27: 0 | H27: 0 | I27: 0 | J27: 0 | K27: 0 | L27: 0 | M27: 0 | N27: 0 | O27: 0 | P27: 0 | Q27: 0 | R27: 0 | S27: 0 | T27: 0 | U27: 0 | V27: 0 | W27: 0 | X27: 0 | Y27: 0 | Z27: 0 | AA27: 0 | AB27: 0 | AC27: 0 | AD27: 0 | AE27: 0 | AF27: 0 | AG27: 0 | AH27: 0 | AI27: 0 | AJ27: 0 | AK27: 0 | AL27: 0 | AM27: 0 | AN27: 0 | AO27: 0 | AP27: 0 | AQ27: 0 | AR27: 0 | AS27: 0 | AT27: 0 | AU27: 0 | AV27: =SUM(H27:AU27) -> 0 | AW27: =F27-AV27 -> 0
B28: GC Overhead | E28: 0 | F28: ='Development Budget'!G16 -> 0 | G28: 0 | H28: 0 | I28: 0 | J28: 0 | K28: 0 | L28: 0 | M28: 0 | N28: 0 | O28: 0 | P28: 0 | Q28: 0 | R28: 0 | S28: 0 | T28: 0 | U28: 0 | V28: 0 | W28: 0 | X28: 0 | Y28: 0 | Z28: 0 | AA28: 0 | AB28: 0 | AC28: 0 | AD28: 0 | AE28: 0 | AF28: 0 | AG28: 0 | AH28: 0 | AI28: 0 | AJ28: 0 | AK28: 0 | AL28: 0 | AM28: 0 | AN28: 0 | AO28: 0 | AP28: 0 | AQ28: 0 | AR28: 0 | AS28: 0 | AT28: 0 | AU28: 0 | AV28: =SUM(H28:AU28) -> 0 | AW28: =F28-AV28 -> 0
B29: GC Profit | E29: 0 | F29: ='Development Budget'!G17 -> 0 | G29: 0 | H29: 0 | I29: 0 | J29: 0 | K29: 0 | L29: 0 | M29: 0 | N29: 0 | O29: 0 | P29: 0 | Q29: 0 | R29: 0 | S29: 0 | T29: 0 | U29: 0 | V29: 0 | W29: 0 | X29: 0 | Y29: 0 | Z29: 0 | AA29: 0 | AB29: 0 | AC29: 0 | AD29: 0 | AE29: 0 | AF29: 0 | AG29: 0 | AH29: 0 | AI29: 0 | AJ29: 0 | AK29: 0 | AL29: 0 | AM29: 0 | AN29: 0 | AO29: 0 | AP29: 0 | AQ29: 0 | AR29: 0 | AS29: 0 | AT29: 0 | AU29: 0 | AV29: =SUM(H29:AU29) -> 0 | AW29: =F29-AV29 -> 0
